[2025-07-25T03:28:58.424+0000] {local_task_job_runner.py:120} INFO - ::group::Pre task execution logs
[2025-07-25T03:28:58.450+0000] {taskinstance.py:2076} INFO - Dependencies all met for dep_context=non-requeueable deps ti=<TaskInstance: bank_data_pipeline.generate_banking_data_2 scheduled__2025-07-24T00:00:00+00:00 [queued]>
[2025-07-25T03:28:58.456+0000] {taskinstance.py:2076} INFO - Dependencies all met for dep_context=requeueable deps ti=<TaskInstance: bank_data_pipeline.generate_banking_data_2 scheduled__2025-07-24T00:00:00+00:00 [queued]>
[2025-07-25T03:28:58.456+0000] {taskinstance.py:2306} INFO - Starting attempt 2 of 3
[2025-07-25T03:28:58.466+0000] {taskinstance.py:2330} INFO - Executing <Task(PythonOperator): generate_banking_data_2> on 2025-07-24 00:00:00+00:00
[2025-07-25T03:28:58.472+0000] {standard_task_runner.py:63} INFO - Started process 331 to run task
[2025-07-25T03:28:58.478+0000] {standard_task_runner.py:90} INFO - Running: ['***', 'tasks', 'run', 'bank_data_pipeline', 'generate_banking_data_2', 'scheduled__2025-07-24T00:00:00+00:00', '--job-id', '3', '--raw', '--subdir', 'DAGS_FOLDER/bank_data_pipeline.py', '--cfg-path', '/tmp/tmpdsk0apae']
[2025-07-25T03:28:58.480+0000] {standard_task_runner.py:91} INFO - Job 3: Subtask generate_banking_data_2
[2025-07-25T03:28:58.493+0000] {logging_mixin.py:188} WARNING - /home/***/.local/lib/python3.10/site-packages/***/settings.py:195 DeprecationWarning: The sql_alchemy_conn option in [core] has been moved to the sql_alchemy_conn option in [database] - the old setting has been used, but please update your config.
[2025-07-25T03:28:58.523+0000] {task_command.py:426} INFO - Running <TaskInstance: bank_data_pipeline.generate_banking_data_2 scheduled__2025-07-24T00:00:00+00:00 [running]> on host e85c0090af14
[2025-07-25T03:28:58.590+0000] {taskinstance.py:2648} INFO - Exporting env vars: AIRFLOW_CTX_DAG_OWNER='data_engineering_team_2' AIRFLOW_CTX_DAG_ID='bank_data_pipeline' AIRFLOW_CTX_TASK_ID='generate_banking_data_2' AIRFLOW_CTX_EXECUTION_DATE='2025-07-24T00:00:00+00:00' AIRFLOW_CTX_TRY_NUMBER='2' AIRFLOW_CTX_DAG_RUN_ID='scheduled__2025-07-24T00:00:00+00:00'
[2025-07-25T03:28:58.591+0000] {taskinstance.py:430} INFO - ::endgroup::
[2025-07-25T03:28:58.600+0000] {bank_data_pipeline.py:71} INFO - Starting data generation for run scheduled__2025-07-24T00:00:00+00:00
[2025-07-25T03:28:58.601+0000] {bank_data_pipeline.py:108} ERROR - Unexpected error in data generation: expected str, bytes or os.PathLike object, not NoneType - expected str, bytes or os.PathLike object, not NoneType
[2025-07-25T03:28:58.601+0000] {taskinstance.py:441} INFO - ::group::Post task execution logs
[2025-07-25T03:28:58.602+0000] {taskinstance.py:2905} ERROR - Task failed with exception
Traceback (most recent call last):
  File "/home/airflow/.local/lib/python3.10/site-packages/airflow/models/taskinstance.py", line 465, in _execute_task
    result = _execute_callable(context=context, **execute_callable_kwargs)
  File "/home/airflow/.local/lib/python3.10/site-packages/airflow/models/taskinstance.py", line 432, in _execute_callable
    return execute_callable(context=context, **execute_callable_kwargs)
  File "/home/airflow/.local/lib/python3.10/site-packages/airflow/models/baseoperator.py", line 400, in wrapper
    return func(self, *args, **kwargs)
  File "/home/airflow/.local/lib/python3.10/site-packages/airflow/operators/python.py", line 235, in execute
    return_value = self.execute_callable()
  File "/home/airflow/.local/lib/python3.10/site-packages/airflow/operators/python.py", line 252, in execute_callable
    return self.python_callable(*self.op_args, **self.op_kwargs)
  File "/opt/airflow/dags/bank_data_pipeline.py", line 80, in generate_banking_data
    result = subprocess.run(
  File "/usr/local/lib/python3.10/subprocess.py", line 503, in run
    with Popen(*popenargs, **kwargs) as process:
  File "/usr/local/lib/python3.10/subprocess.py", line 971, in __init__
    self._execute_child(args, executable, preexec_fn, close_fds,
  File "/usr/local/lib/python3.10/subprocess.py", line 1796, in _execute_child
    self.pid = _posixsubprocess.fork_exec(
TypeError: expected str, bytes or os.PathLike object, not NoneType
[2025-07-25T03:28:58.610+0000] {taskinstance.py:1206} INFO - Marking task as UP_FOR_RETRY. dag_id=bank_data_pipeline, task_id=generate_banking_data_2, run_id=scheduled__2025-07-24T00:00:00+00:00, execution_date=20250724T000000, start_date=20250725T032858, end_date=20250725T032858
[2025-07-25T03:28:58.618+0000] {standard_task_runner.py:110} ERROR - Failed to execute job 3 for task generate_banking_data_2 (expected str, bytes or os.PathLike object, not NoneType; 331)
[2025-07-25T03:28:58.650+0000] {local_task_job_runner.py:240} INFO - Task exited with return code 1
[2025-07-25T03:28:58.671+0000] {taskinstance.py:3498} INFO - 0 downstream tasks scheduled from follow-on schedule check
[2025-07-25T03:28:58.673+0000] {local_task_job_runner.py:222} INFO - ::endgroup::
