[2025-07-16T16:11:16.238+0000] {local_task_job_runner.py:120} INFO - ::group::Pre task execution logs
[2025-07-16T16:11:16.271+0000] {taskinstance.py:2076} INFO - Dependencies all met for dep_context=non-requeueable deps ti=<TaskInstance: bank_data_pipeline.generate_banking_data scheduled__2025-07-15T00:00:00+00:00 [queued]>
[2025-07-16T16:11:16.279+0000] {taskinstance.py:2076} INFO - Dependencies all met for dep_context=requeueable deps ti=<TaskInstance: bank_data_pipeline.generate_banking_data scheduled__2025-07-15T00:00:00+00:00 [queued]>
[2025-07-16T16:11:16.279+0000] {taskinstance.py:2306} INFO - Starting attempt 1 of 3
[2025-07-16T16:11:16.289+0000] {taskinstance.py:2330} INFO - Executing <Task(PythonOperator): generate_banking_data> on 2025-07-15 00:00:00+00:00
[2025-07-16T16:11:16.297+0000] {logging_mixin.py:188} WARNING - /home/***/.local/lib/python3.12/site-packages/***/task/task_runner/standard_task_runner.py:61 DeprecationWarning: This process (pid=244) is multi-threaded, use of fork() may lead to deadlocks in the child.
[2025-07-16T16:11:16.298+0000] {standard_task_runner.py:63} INFO - Started process 245 to run task
[2025-07-16T16:11:16.299+0000] {standard_task_runner.py:90} INFO - Running: ['***', 'tasks', 'run', 'bank_data_pipeline', 'generate_banking_data', 'scheduled__2025-07-15T00:00:00+00:00', '--job-id', '4', '--raw', '--subdir', 'DAGS_FOLDER/bank_data_pipeline.py', '--cfg-path', '/tmp/tmpe4gyeez2']
[2025-07-16T16:11:16.302+0000] {standard_task_runner.py:91} INFO - Job 4: Subtask generate_banking_data
[2025-07-16T16:11:16.318+0000] {logging_mixin.py:188} WARNING - /home/***/.local/lib/python3.12/site-packages/***/settings.py:195 DeprecationWarning: The sql_alchemy_conn option in [core] has been moved to the sql_alchemy_conn option in [database] - the old setting has been used, but please update your config.
[2025-07-16T16:11:16.353+0000] {task_command.py:426} INFO - Running <TaskInstance: bank_data_pipeline.generate_banking_data scheduled__2025-07-15T00:00:00+00:00 [running]> on host 3f78294f0070
[2025-07-16T16:11:16.439+0000] {taskinstance.py:2648} INFO - Exporting env vars: AIRFLOW_CTX_DAG_OWNER='data_engineering_team' AIRFLOW_CTX_DAG_ID='bank_data_pipeline' AIRFLOW_CTX_TASK_ID='generate_banking_data' AIRFLOW_CTX_EXECUTION_DATE='2025-07-15T00:00:00+00:00' AIRFLOW_CTX_TRY_NUMBER='1' AIRFLOW_CTX_DAG_RUN_ID='scheduled__2025-07-15T00:00:00+00:00'
[2025-07-16T16:11:16.440+0000] {taskinstance.py:430} INFO - ::endgroup::
[2025-07-16T16:11:16.451+0000] {logging_mixin.py:188} INFO - 2025-07-16 16:11:16,451 - pipeline_logger - INFO - Starting data generation for run scheduled__2025-07-15T00:00:00+00:00
[2025-07-16T16:11:16.451+0000] {pipeline_logger.py:224} INFO - Starting data generation for run scheduled__2025-07-15T00:00:00+00:00
[2025-07-16T16:11:16.650+0000] {logging_mixin.py:188} INFO - 2025-07-16 16:11:16,649 - pipeline_logger - ERROR - Pipeline error in generate_banking_data: Data generation failed: Traceback (most recent call last):
  File "/opt/***/src/generate_data_***.py", line 8, in <module>
    from faker import Faker
ModuleNotFoundError: No module named 'faker'
[2025-07-16T16:11:16.649+0000] {pipeline_logger.py:194} ERROR - Pipeline error in generate_banking_data: Data generation failed: Traceback (most recent call last):
  File "/opt/***/src/generate_data_***.py", line 8, in <module>
    from faker import Faker
ModuleNotFoundError: No module named 'faker'

[2025-07-16T16:11:16.664+0000] {logging_mixin.py:188} INFO - 2025-07-16 16:11:16,664 - pipeline_logger - ERROR - Pipeline error in generate_banking_data: Unexpected error in data generation: Data generation failed: Traceback (most recent call last):
  File "/opt/***/src/generate_data_***.py", line 8, in <module>
    from faker import Faker
ModuleNotFoundError: No module named 'faker'
[2025-07-16T16:11:16.664+0000] {pipeline_logger.py:194} ERROR - Pipeline error in generate_banking_data: Unexpected error in data generation: Data generation failed: Traceback (most recent call last):
  File "/opt/***/src/generate_data_***.py", line 8, in <module>
    from faker import Faker
ModuleNotFoundError: No module named 'faker'

[2025-07-16T16:11:16.665+0000] {taskinstance.py:441} INFO - ::group::Post task execution logs
[2025-07-16T16:11:16.682+0000] {taskinstance.py:2905} ERROR - Task failed with exception
Traceback (most recent call last):
  File "/home/airflow/.local/lib/python3.12/site-packages/airflow/models/taskinstance.py", line 465, in _execute_task
    result = _execute_callable(context=context, **execute_callable_kwargs)
             ^^^^^^^^^^^^^^^^^^^^^^^^^^^^^^^^^^^^^^^^^^^^^^^^^^^^^^^^^^^^^
  File "/home/airflow/.local/lib/python3.12/site-packages/airflow/models/taskinstance.py", line 432, in _execute_callable
    return execute_callable(context=context, **execute_callable_kwargs)
           ^^^^^^^^^^^^^^^^^^^^^^^^^^^^^^^^^^^^^^^^^^^^^^^^^^^^^^^^^^^^
  File "/home/airflow/.local/lib/python3.12/site-packages/airflow/models/baseoperator.py", line 400, in wrapper
    return func(self, *args, **kwargs)
           ^^^^^^^^^^^^^^^^^^^^^^^^^^^
  File "/home/airflow/.local/lib/python3.12/site-packages/airflow/operators/python.py", line 235, in execute
    return_value = self.execute_callable()
                   ^^^^^^^^^^^^^^^^^^^^^^^
  File "/home/airflow/.local/lib/python3.12/site-packages/airflow/operators/python.py", line 252, in execute_callable
    return self.python_callable(*self.op_args, **self.op_kwargs)
           ^^^^^^^^^^^^^^^^^^^^^^^^^^^^^^^^^^^^^^^^^^^^^^^^^^^^^
  File "/opt/airflow/dags/bank_data_pipeline.py", line 102, in generate_banking_data
    raise AirflowException(error_msg)
airflow.exceptions.AirflowException: Data generation failed: Traceback (most recent call last):
  File "/opt/***/src/generate_data_***.py", line 8, in <module>
    from faker import Faker
ModuleNotFoundError: No module named 'faker'

[2025-07-16T16:11:16.688+0000] {taskinstance.py:1206} INFO - Marking task as UP_FOR_RETRY. dag_id=bank_data_pipeline, task_id=generate_banking_data, run_id=scheduled__2025-07-15T00:00:00+00:00, execution_date=20250715T000000, start_date=20250716T161116, end_date=20250716T161116
[2025-07-16T16:11:16.702+0000] {standard_task_runner.py:110} ERROR - Failed to execute job 4 for task generate_banking_data (Data generation failed: Traceback (most recent call last):
  File "/opt/***/src/generate_data_***.py", line 8, in <module>
    from faker import Faker
ModuleNotFoundError: No module named 'faker'
; 245)
[2025-07-16T16:11:16.712+0000] {local_task_job_runner.py:240} INFO - Task exited with return code 1
[2025-07-16T16:11:16.755+0000] {taskinstance.py:3498} INFO - 0 downstream tasks scheduled from follow-on schedule check
[2025-07-16T16:11:16.756+0000] {local_task_job_runner.py:222} INFO - ::endgroup::
[2025-07-16T16:20:16.966+0000] {local_task_job_runner.py:120} INFO - ::group::Pre task execution logs
[2025-07-16T16:20:16.999+0000] {taskinstance.py:2076} INFO - Dependencies all met for dep_context=non-requeueable deps ti=<TaskInstance: bank_data_pipeline.generate_banking_data scheduled__2025-07-15T00:00:00+00:00 [queued]>
[2025-07-16T16:20:17.006+0000] {taskinstance.py:2076} INFO - Dependencies all met for dep_context=requeueable deps ti=<TaskInstance: bank_data_pipeline.generate_banking_data scheduled__2025-07-15T00:00:00+00:00 [queued]>
[2025-07-16T16:20:17.006+0000] {taskinstance.py:2306} INFO - Starting attempt 1 of 3
[2025-07-16T16:20:17.016+0000] {taskinstance.py:2330} INFO - Executing <Task(PythonOperator): generate_banking_data> on 2025-07-15 00:00:00+00:00
[2025-07-16T16:20:17.024+0000] {logging_mixin.py:188} WARNING - /home/***/.local/lib/python3.12/site-packages/***/task/task_runner/standard_task_runner.py:61 DeprecationWarning: This process (pid=215) is multi-threaded, use of fork() may lead to deadlocks in the child.
[2025-07-16T16:20:17.025+0000] {standard_task_runner.py:63} INFO - Started process 216 to run task
[2025-07-16T16:20:17.025+0000] {standard_task_runner.py:90} INFO - Running: ['***', 'tasks', 'run', 'bank_data_pipeline', 'generate_banking_data', 'scheduled__2025-07-15T00:00:00+00:00', '--job-id', '4', '--raw', '--subdir', 'DAGS_FOLDER/bank_data_pipeline.py', '--cfg-path', '/tmp/tmp4pu7kcwl']
[2025-07-16T16:20:17.027+0000] {standard_task_runner.py:91} INFO - Job 4: Subtask generate_banking_data
[2025-07-16T16:20:17.041+0000] {logging_mixin.py:188} WARNING - /home/***/.local/lib/python3.12/site-packages/***/settings.py:195 DeprecationWarning: The sql_alchemy_conn option in [core] has been moved to the sql_alchemy_conn option in [database] - the old setting has been used, but please update your config.
[2025-07-16T16:20:17.079+0000] {task_command.py:426} INFO - Running <TaskInstance: bank_data_pipeline.generate_banking_data scheduled__2025-07-15T00:00:00+00:00 [running]> on host 3a97a985f8ee
[2025-07-16T16:20:17.160+0000] {taskinstance.py:2648} INFO - Exporting env vars: AIRFLOW_CTX_DAG_OWNER='data_engineering_team' AIRFLOW_CTX_DAG_ID='bank_data_pipeline' AIRFLOW_CTX_TASK_ID='generate_banking_data' AIRFLOW_CTX_EXECUTION_DATE='2025-07-15T00:00:00+00:00' AIRFLOW_CTX_TRY_NUMBER='1' AIRFLOW_CTX_DAG_RUN_ID='scheduled__2025-07-15T00:00:00+00:00'
[2025-07-16T16:20:17.161+0000] {taskinstance.py:430} INFO - ::endgroup::
[2025-07-16T16:20:17.172+0000] {logging_mixin.py:188} INFO - 2025-07-16 16:20:17,172 - pipeline_logger - INFO - Starting data generation for run scheduled__2025-07-15T00:00:00+00:00
[2025-07-16T16:20:17.172+0000] {pipeline_logger.py:224} INFO - Starting data generation for run scheduled__2025-07-15T00:00:00+00:00
[2025-07-16T16:20:17.366+0000] {logging_mixin.py:188} INFO - 2025-07-16 16:20:17,366 - pipeline_logger - ERROR - Pipeline error in generate_banking_data: Data generation failed: Traceback (most recent call last):
  File "/opt/***/src/generate_data_***.py", line 8, in <module>
    from faker import Faker
ModuleNotFoundError: No module named 'faker'
[2025-07-16T16:20:17.366+0000] {pipeline_logger.py:194} ERROR - Pipeline error in generate_banking_data: Data generation failed: Traceback (most recent call last):
  File "/opt/***/src/generate_data_***.py", line 8, in <module>
    from faker import Faker
ModuleNotFoundError: No module named 'faker'

[2025-07-16T16:20:17.376+0000] {logging_mixin.py:188} INFO - 2025-07-16 16:20:17,375 - pipeline_logger - ERROR - Pipeline error in generate_banking_data: Unexpected error in data generation: Data generation failed: Traceback (most recent call last):
  File "/opt/***/src/generate_data_***.py", line 8, in <module>
    from faker import Faker
ModuleNotFoundError: No module named 'faker'
[2025-07-16T16:20:17.375+0000] {pipeline_logger.py:194} ERROR - Pipeline error in generate_banking_data: Unexpected error in data generation: Data generation failed: Traceback (most recent call last):
  File "/opt/***/src/generate_data_***.py", line 8, in <module>
    from faker import Faker
ModuleNotFoundError: No module named 'faker'

[2025-07-16T16:20:17.376+0000] {taskinstance.py:441} INFO - ::group::Post task execution logs
[2025-07-16T16:20:17.389+0000] {taskinstance.py:2905} ERROR - Task failed with exception
Traceback (most recent call last):
  File "/home/airflow/.local/lib/python3.12/site-packages/airflow/models/taskinstance.py", line 465, in _execute_task
    result = _execute_callable(context=context, **execute_callable_kwargs)
             ^^^^^^^^^^^^^^^^^^^^^^^^^^^^^^^^^^^^^^^^^^^^^^^^^^^^^^^^^^^^^
  File "/home/airflow/.local/lib/python3.12/site-packages/airflow/models/taskinstance.py", line 432, in _execute_callable
    return execute_callable(context=context, **execute_callable_kwargs)
           ^^^^^^^^^^^^^^^^^^^^^^^^^^^^^^^^^^^^^^^^^^^^^^^^^^^^^^^^^^^^
  File "/home/airflow/.local/lib/python3.12/site-packages/airflow/models/baseoperator.py", line 400, in wrapper
    return func(self, *args, **kwargs)
           ^^^^^^^^^^^^^^^^^^^^^^^^^^^
  File "/home/airflow/.local/lib/python3.12/site-packages/airflow/operators/python.py", line 235, in execute
    return_value = self.execute_callable()
                   ^^^^^^^^^^^^^^^^^^^^^^^
  File "/home/airflow/.local/lib/python3.12/site-packages/airflow/operators/python.py", line 252, in execute_callable
    return self.python_callable(*self.op_args, **self.op_kwargs)
           ^^^^^^^^^^^^^^^^^^^^^^^^^^^^^^^^^^^^^^^^^^^^^^^^^^^^^
  File "/opt/airflow/dags/bank_data_pipeline.py", line 102, in generate_banking_data
    raise AirflowException(error_msg)
airflow.exceptions.AirflowException: Data generation failed: Traceback (most recent call last):
  File "/opt/***/src/generate_data_***.py", line 8, in <module>
    from faker import Faker
ModuleNotFoundError: No module named 'faker'

[2025-07-16T16:20:17.393+0000] {taskinstance.py:1206} INFO - Marking task as UP_FOR_RETRY. dag_id=bank_data_pipeline, task_id=generate_banking_data, run_id=scheduled__2025-07-15T00:00:00+00:00, execution_date=20250715T000000, start_date=20250716T162016, end_date=20250716T162017
[2025-07-16T16:20:17.412+0000] {standard_task_runner.py:110} ERROR - Failed to execute job 4 for task generate_banking_data (Data generation failed: Traceback (most recent call last):
  File "/opt/***/src/generate_data_***.py", line 8, in <module>
    from faker import Faker
ModuleNotFoundError: No module named 'faker'
; 216)
[2025-07-16T16:20:17.439+0000] {local_task_job_runner.py:240} INFO - Task exited with return code 1
[2025-07-16T16:20:17.489+0000] {taskinstance.py:3498} INFO - 0 downstream tasks scheduled from follow-on schedule check
[2025-07-16T16:20:17.491+0000] {local_task_job_runner.py:222} INFO - ::endgroup::
[2025-07-16T16:23:09.186+0000] {local_task_job_runner.py:120} INFO - ::group::Pre task execution logs
[2025-07-16T16:23:09.220+0000] {taskinstance.py:2076} INFO - Dependencies all met for dep_context=non-requeueable deps ti=<TaskInstance: bank_data_pipeline.generate_banking_data scheduled__2025-07-15T00:00:00+00:00 [queued]>
[2025-07-16T16:23:09.228+0000] {taskinstance.py:2076} INFO - Dependencies all met for dep_context=requeueable deps ti=<TaskInstance: bank_data_pipeline.generate_banking_data scheduled__2025-07-15T00:00:00+00:00 [queued]>
[2025-07-16T16:23:09.229+0000] {taskinstance.py:2306} INFO - Starting attempt 1 of 3
[2025-07-16T16:23:09.239+0000] {taskinstance.py:2330} INFO - Executing <Task(PythonOperator): generate_banking_data> on 2025-07-15 00:00:00+00:00
[2025-07-16T16:23:09.247+0000] {logging_mixin.py:188} WARNING - /home/***/.local/lib/python3.12/site-packages/***/task/task_runner/standard_task_runner.py:61 DeprecationWarning: This process (pid=228) is multi-threaded, use of fork() may lead to deadlocks in the child.
[2025-07-16T16:23:09.247+0000] {standard_task_runner.py:63} INFO - Started process 229 to run task
[2025-07-16T16:23:09.248+0000] {standard_task_runner.py:90} INFO - Running: ['***', 'tasks', 'run', 'bank_data_pipeline', 'generate_banking_data', 'scheduled__2025-07-15T00:00:00+00:00', '--job-id', '4', '--raw', '--subdir', 'DAGS_FOLDER/bank_data_pipeline.py', '--cfg-path', '/tmp/tmp8z8w1ev5']
[2025-07-16T16:23:09.251+0000] {standard_task_runner.py:91} INFO - Job 4: Subtask generate_banking_data
[2025-07-16T16:23:09.265+0000] {logging_mixin.py:188} WARNING - /home/***/.local/lib/python3.12/site-packages/***/settings.py:195 DeprecationWarning: The sql_alchemy_conn option in [core] has been moved to the sql_alchemy_conn option in [database] - the old setting has been used, but please update your config.
[2025-07-16T16:23:09.302+0000] {task_command.py:426} INFO - Running <TaskInstance: bank_data_pipeline.generate_banking_data scheduled__2025-07-15T00:00:00+00:00 [running]> on host fee2a1e1d73e
[2025-07-16T16:23:09.382+0000] {taskinstance.py:2648} INFO - Exporting env vars: AIRFLOW_CTX_DAG_OWNER='data_engineering_team' AIRFLOW_CTX_DAG_ID='bank_data_pipeline' AIRFLOW_CTX_TASK_ID='generate_banking_data' AIRFLOW_CTX_EXECUTION_DATE='2025-07-15T00:00:00+00:00' AIRFLOW_CTX_TRY_NUMBER='1' AIRFLOW_CTX_DAG_RUN_ID='scheduled__2025-07-15T00:00:00+00:00'
[2025-07-16T16:23:09.382+0000] {taskinstance.py:430} INFO - ::endgroup::
[2025-07-16T16:23:09.393+0000] {logging_mixin.py:188} INFO - 2025-07-16 16:23:09,393 - pipeline_logger - INFO - Starting data generation for run scheduled__2025-07-15T00:00:00+00:00
[2025-07-16T16:23:09.393+0000] {pipeline_logger.py:224} INFO - Starting data generation for run scheduled__2025-07-15T00:00:00+00:00
[2025-07-16T16:23:09.583+0000] {logging_mixin.py:188} INFO - 2025-07-16 16:23:09,583 - pipeline_logger - ERROR - Pipeline error in generate_banking_data: Data generation failed: Traceback (most recent call last):
  File "/opt/***/src/generate_data_***.py", line 8, in <module>
    from faker import Faker
ModuleNotFoundError: No module named 'faker'
[2025-07-16T16:23:09.583+0000] {pipeline_logger.py:194} ERROR - Pipeline error in generate_banking_data: Data generation failed: Traceback (most recent call last):
  File "/opt/***/src/generate_data_***.py", line 8, in <module>
    from faker import Faker
ModuleNotFoundError: No module named 'faker'

[2025-07-16T16:23:09.593+0000] {logging_mixin.py:188} INFO - 2025-07-16 16:23:09,593 - pipeline_logger - ERROR - Pipeline error in generate_banking_data: Unexpected error in data generation: Data generation failed: Traceback (most recent call last):
  File "/opt/***/src/generate_data_***.py", line 8, in <module>
    from faker import Faker
ModuleNotFoundError: No module named 'faker'
[2025-07-16T16:23:09.593+0000] {pipeline_logger.py:194} ERROR - Pipeline error in generate_banking_data: Unexpected error in data generation: Data generation failed: Traceback (most recent call last):
  File "/opt/***/src/generate_data_***.py", line 8, in <module>
    from faker import Faker
ModuleNotFoundError: No module named 'faker'

[2025-07-16T16:23:09.593+0000] {taskinstance.py:441} INFO - ::group::Post task execution logs
[2025-07-16T16:23:09.608+0000] {taskinstance.py:2905} ERROR - Task failed with exception
Traceback (most recent call last):
  File "/home/airflow/.local/lib/python3.12/site-packages/airflow/models/taskinstance.py", line 465, in _execute_task
    result = _execute_callable(context=context, **execute_callable_kwargs)
             ^^^^^^^^^^^^^^^^^^^^^^^^^^^^^^^^^^^^^^^^^^^^^^^^^^^^^^^^^^^^^
  File "/home/airflow/.local/lib/python3.12/site-packages/airflow/models/taskinstance.py", line 432, in _execute_callable
    return execute_callable(context=context, **execute_callable_kwargs)
           ^^^^^^^^^^^^^^^^^^^^^^^^^^^^^^^^^^^^^^^^^^^^^^^^^^^^^^^^^^^^
  File "/home/airflow/.local/lib/python3.12/site-packages/airflow/models/baseoperator.py", line 400, in wrapper
    return func(self, *args, **kwargs)
           ^^^^^^^^^^^^^^^^^^^^^^^^^^^
  File "/home/airflow/.local/lib/python3.12/site-packages/airflow/operators/python.py", line 235, in execute
    return_value = self.execute_callable()
                   ^^^^^^^^^^^^^^^^^^^^^^^
  File "/home/airflow/.local/lib/python3.12/site-packages/airflow/operators/python.py", line 252, in execute_callable
    return self.python_callable(*self.op_args, **self.op_kwargs)
           ^^^^^^^^^^^^^^^^^^^^^^^^^^^^^^^^^^^^^^^^^^^^^^^^^^^^^
  File "/opt/airflow/dags/bank_data_pipeline.py", line 102, in generate_banking_data
    raise AirflowException(error_msg)
airflow.exceptions.AirflowException: Data generation failed: Traceback (most recent call last):
  File "/opt/***/src/generate_data_***.py", line 8, in <module>
    from faker import Faker
ModuleNotFoundError: No module named 'faker'

[2025-07-16T16:23:09.614+0000] {taskinstance.py:1206} INFO - Marking task as UP_FOR_RETRY. dag_id=bank_data_pipeline, task_id=generate_banking_data, run_id=scheduled__2025-07-15T00:00:00+00:00, execution_date=20250715T000000, start_date=20250716T162309, end_date=20250716T162309
[2025-07-16T16:23:09.629+0000] {standard_task_runner.py:110} ERROR - Failed to execute job 4 for task generate_banking_data (Data generation failed: Traceback (most recent call last):
  File "/opt/***/src/generate_data_***.py", line 8, in <module>
    from faker import Faker
ModuleNotFoundError: No module named 'faker'
; 229)
[2025-07-16T16:23:09.662+0000] {local_task_job_runner.py:240} INFO - Task exited with return code 1
[2025-07-16T16:23:09.702+0000] {taskinstance.py:3498} INFO - 0 downstream tasks scheduled from follow-on schedule check
[2025-07-16T16:23:09.703+0000] {local_task_job_runner.py:222} INFO - ::endgroup::
[2025-07-16T16:29:43.771+0000] {local_task_job_runner.py:120} INFO - ::group::Pre task execution logs
[2025-07-16T16:29:43.803+0000] {taskinstance.py:2076} INFO - Dependencies all met for dep_context=non-requeueable deps ti=<TaskInstance: bank_data_pipeline.generate_banking_data scheduled__2025-07-15T00:00:00+00:00 [queued]>
[2025-07-16T16:29:43.811+0000] {taskinstance.py:2076} INFO - Dependencies all met for dep_context=requeueable deps ti=<TaskInstance: bank_data_pipeline.generate_banking_data scheduled__2025-07-15T00:00:00+00:00 [queued]>
[2025-07-16T16:29:43.811+0000] {taskinstance.py:2306} INFO - Starting attempt 1 of 3
[2025-07-16T16:29:43.822+0000] {taskinstance.py:2330} INFO - Executing <Task(PythonOperator): generate_banking_data> on 2025-07-15 00:00:00+00:00
[2025-07-16T16:29:43.829+0000] {logging_mixin.py:188} WARNING - /home/***/.local/lib/python3.12/site-packages/***/task/task_runner/standard_task_runner.py:61 DeprecationWarning: This process (pid=205) is multi-threaded, use of fork() may lead to deadlocks in the child.
[2025-07-16T16:29:43.830+0000] {standard_task_runner.py:63} INFO - Started process 206 to run task
[2025-07-16T16:29:43.831+0000] {standard_task_runner.py:90} INFO - Running: ['***', 'tasks', 'run', 'bank_data_pipeline', 'generate_banking_data', 'scheduled__2025-07-15T00:00:00+00:00', '--job-id', '4', '--raw', '--subdir', 'DAGS_FOLDER/bank_data_pipeline.py', '--cfg-path', '/tmp/tmpg68qsb24']
[2025-07-16T16:29:43.834+0000] {standard_task_runner.py:91} INFO - Job 4: Subtask generate_banking_data
[2025-07-16T16:29:43.851+0000] {logging_mixin.py:188} WARNING - /home/***/.local/lib/python3.12/site-packages/***/settings.py:195 DeprecationWarning: The sql_alchemy_conn option in [core] has been moved to the sql_alchemy_conn option in [database] - the old setting has been used, but please update your config.
[2025-07-16T16:29:43.886+0000] {task_command.py:426} INFO - Running <TaskInstance: bank_data_pipeline.generate_banking_data scheduled__2025-07-15T00:00:00+00:00 [running]> on host 07a1f2c7fa0b
[2025-07-16T16:29:43.962+0000] {taskinstance.py:2648} INFO - Exporting env vars: AIRFLOW_CTX_DAG_OWNER='data_engineering_team' AIRFLOW_CTX_DAG_ID='bank_data_pipeline' AIRFLOW_CTX_TASK_ID='generate_banking_data' AIRFLOW_CTX_EXECUTION_DATE='2025-07-15T00:00:00+00:00' AIRFLOW_CTX_TRY_NUMBER='1' AIRFLOW_CTX_DAG_RUN_ID='scheduled__2025-07-15T00:00:00+00:00'
[2025-07-16T16:29:43.963+0000] {taskinstance.py:430} INFO - ::endgroup::
[2025-07-16T16:29:43.975+0000] {logging_mixin.py:188} INFO - 2025-07-16 16:29:43,975 - pipeline_logger - INFO - Starting data generation for run scheduled__2025-07-15T00:00:00+00:00
[2025-07-16T16:29:43.975+0000] {pipeline_logger.py:224} INFO - Starting data generation for run scheduled__2025-07-15T00:00:00+00:00
[2025-07-16T16:29:44.212+0000] {logging_mixin.py:188} INFO - 2025-07-16 16:29:44,212 - pipeline_logger - ERROR - Pipeline error in generate_banking_data: Data generation failed: Traceback (most recent call last):
  File "/opt/***/src/generate_data_***.py", line 8, in <module>
    from faker import Faker
ModuleNotFoundError: No module named 'faker'
[2025-07-16T16:29:44.212+0000] {pipeline_logger.py:194} ERROR - Pipeline error in generate_banking_data: Data generation failed: Traceback (most recent call last):
  File "/opt/***/src/generate_data_***.py", line 8, in <module>
    from faker import Faker
ModuleNotFoundError: No module named 'faker'

[2025-07-16T16:29:44.223+0000] {logging_mixin.py:188} INFO - 2025-07-16 16:29:44,223 - pipeline_logger - ERROR - Pipeline error in generate_banking_data: Unexpected error in data generation: Data generation failed: Traceback (most recent call last):
  File "/opt/***/src/generate_data_***.py", line 8, in <module>
    from faker import Faker
ModuleNotFoundError: No module named 'faker'
[2025-07-16T16:29:44.223+0000] {pipeline_logger.py:194} ERROR - Pipeline error in generate_banking_data: Unexpected error in data generation: Data generation failed: Traceback (most recent call last):
  File "/opt/***/src/generate_data_***.py", line 8, in <module>
    from faker import Faker
ModuleNotFoundError: No module named 'faker'

[2025-07-16T16:29:44.224+0000] {taskinstance.py:441} INFO - ::group::Post task execution logs
[2025-07-16T16:29:44.239+0000] {taskinstance.py:2905} ERROR - Task failed with exception
Traceback (most recent call last):
  File "/home/airflow/.local/lib/python3.12/site-packages/airflow/models/taskinstance.py", line 465, in _execute_task
    result = _execute_callable(context=context, **execute_callable_kwargs)
             ^^^^^^^^^^^^^^^^^^^^^^^^^^^^^^^^^^^^^^^^^^^^^^^^^^^^^^^^^^^^^
  File "/home/airflow/.local/lib/python3.12/site-packages/airflow/models/taskinstance.py", line 432, in _execute_callable
    return execute_callable(context=context, **execute_callable_kwargs)
           ^^^^^^^^^^^^^^^^^^^^^^^^^^^^^^^^^^^^^^^^^^^^^^^^^^^^^^^^^^^^
  File "/home/airflow/.local/lib/python3.12/site-packages/airflow/models/baseoperator.py", line 400, in wrapper
    return func(self, *args, **kwargs)
           ^^^^^^^^^^^^^^^^^^^^^^^^^^^
  File "/home/airflow/.local/lib/python3.12/site-packages/airflow/operators/python.py", line 235, in execute
    return_value = self.execute_callable()
                   ^^^^^^^^^^^^^^^^^^^^^^^
  File "/home/airflow/.local/lib/python3.12/site-packages/airflow/operators/python.py", line 252, in execute_callable
    return self.python_callable(*self.op_args, **self.op_kwargs)
           ^^^^^^^^^^^^^^^^^^^^^^^^^^^^^^^^^^^^^^^^^^^^^^^^^^^^^
  File "/opt/airflow/dags/bank_data_pipeline.py", line 102, in generate_banking_data
    raise AirflowException(error_msg)
airflow.exceptions.AirflowException: Data generation failed: Traceback (most recent call last):
  File "/opt/***/src/generate_data_***.py", line 8, in <module>
    from faker import Faker
ModuleNotFoundError: No module named 'faker'

[2025-07-16T16:29:44.243+0000] {taskinstance.py:1206} INFO - Marking task as UP_FOR_RETRY. dag_id=bank_data_pipeline, task_id=generate_banking_data, run_id=scheduled__2025-07-15T00:00:00+00:00, execution_date=20250715T000000, start_date=20250716T162943, end_date=20250716T162944
[2025-07-16T16:29:44.252+0000] {standard_task_runner.py:110} ERROR - Failed to execute job 4 for task generate_banking_data (Data generation failed: Traceback (most recent call last):
  File "/opt/***/src/generate_data_***.py", line 8, in <module>
    from faker import Faker
ModuleNotFoundError: No module named 'faker'
; 206)
[2025-07-16T16:29:44.285+0000] {local_task_job_runner.py:240} INFO - Task exited with return code 1
[2025-07-16T16:29:44.337+0000] {taskinstance.py:3498} INFO - 0 downstream tasks scheduled from follow-on schedule check
[2025-07-16T16:29:44.339+0000] {local_task_job_runner.py:222} INFO - ::endgroup::
[2025-07-16T16:43:37.810+0000] {local_task_job_runner.py:120} INFO - ::group::Pre task execution logs
[2025-07-16T16:43:37.856+0000] {taskinstance.py:2076} INFO - Dependencies all met for dep_context=non-requeueable deps ti=<TaskInstance: bank_data_pipeline.generate_banking_data scheduled__2025-07-15T00:00:00+00:00 [queued]>
[2025-07-16T16:43:37.867+0000] {taskinstance.py:2076} INFO - Dependencies all met for dep_context=requeueable deps ti=<TaskInstance: bank_data_pipeline.generate_banking_data scheduled__2025-07-15T00:00:00+00:00 [queued]>
[2025-07-16T16:43:37.868+0000] {taskinstance.py:2306} INFO - Starting attempt 1 of 3
[2025-07-16T16:43:37.882+0000] {taskinstance.py:2330} INFO - Executing <Task(PythonOperator): generate_banking_data> on 2025-07-15 00:00:00+00:00
[2025-07-16T16:43:37.891+0000] {logging_mixin.py:188} WARNING - /home/***/.local/lib/python3.12/site-packages/***/task/task_runner/standard_task_runner.py:61 DeprecationWarning: This process (pid=393) is multi-threaded, use of fork() may lead to deadlocks in the child.
[2025-07-16T16:43:37.892+0000] {standard_task_runner.py:63} INFO - Started process 401 to run task
[2025-07-16T16:43:37.893+0000] {standard_task_runner.py:90} INFO - Running: ['***', 'tasks', 'run', 'bank_data_pipeline', 'generate_banking_data', 'scheduled__2025-07-15T00:00:00+00:00', '--job-id', '4', '--raw', '--subdir', 'DAGS_FOLDER/bank_data_pipeline.py', '--cfg-path', '/tmp/tmppqqe8e8p']
[2025-07-16T16:43:37.895+0000] {standard_task_runner.py:91} INFO - Job 4: Subtask generate_banking_data
[2025-07-16T16:43:37.911+0000] {logging_mixin.py:188} WARNING - /home/***/.local/lib/python3.12/site-packages/***/settings.py:195 DeprecationWarning: The sql_alchemy_conn option in [core] has been moved to the sql_alchemy_conn option in [database] - the old setting has been used, but please update your config.
[2025-07-16T16:43:37.949+0000] {task_command.py:426} INFO - Running <TaskInstance: bank_data_pipeline.generate_banking_data scheduled__2025-07-15T00:00:00+00:00 [running]> on host 6033db535fcd
[2025-07-16T16:43:38.028+0000] {taskinstance.py:2648} INFO - Exporting env vars: AIRFLOW_CTX_DAG_OWNER='data_engineering_team' AIRFLOW_CTX_DAG_ID='bank_data_pipeline' AIRFLOW_CTX_TASK_ID='generate_banking_data' AIRFLOW_CTX_EXECUTION_DATE='2025-07-15T00:00:00+00:00' AIRFLOW_CTX_TRY_NUMBER='1' AIRFLOW_CTX_DAG_RUN_ID='scheduled__2025-07-15T00:00:00+00:00'
[2025-07-16T16:43:38.029+0000] {taskinstance.py:430} INFO - ::endgroup::
[2025-07-16T16:43:38.040+0000] {logging_mixin.py:188} INFO - 2025-07-16 16:43:38,040 - pipeline_logger - INFO - Starting data generation for run scheduled__2025-07-15T00:00:00+00:00
[2025-07-16T16:43:38.040+0000] {pipeline_logger.py:224} INFO - Starting data generation for run scheduled__2025-07-15T00:00:00+00:00
[2025-07-16T16:43:38.245+0000] {logging_mixin.py:188} INFO - 2025-07-16 16:43:38,245 - pipeline_logger - ERROR - Pipeline error in generate_banking_data: Data generation failed: Traceback (most recent call last):
  File "/opt/***/src/generate_data_***.py", line 8, in <module>
    from faker import Faker
ModuleNotFoundError: No module named 'faker'
[2025-07-16T16:43:38.245+0000] {pipeline_logger.py:194} ERROR - Pipeline error in generate_banking_data: Data generation failed: Traceback (most recent call last):
  File "/opt/***/src/generate_data_***.py", line 8, in <module>
    from faker import Faker
ModuleNotFoundError: No module named 'faker'

[2025-07-16T16:43:38.259+0000] {logging_mixin.py:188} INFO - 2025-07-16 16:43:38,259 - pipeline_logger - ERROR - Pipeline error in generate_banking_data: Unexpected error in data generation: Data generation failed: Traceback (most recent call last):
  File "/opt/***/src/generate_data_***.py", line 8, in <module>
    from faker import Faker
ModuleNotFoundError: No module named 'faker'
[2025-07-16T16:43:38.259+0000] {pipeline_logger.py:194} ERROR - Pipeline error in generate_banking_data: Unexpected error in data generation: Data generation failed: Traceback (most recent call last):
  File "/opt/***/src/generate_data_***.py", line 8, in <module>
    from faker import Faker
ModuleNotFoundError: No module named 'faker'

[2025-07-16T16:43:38.260+0000] {taskinstance.py:441} INFO - ::group::Post task execution logs
[2025-07-16T16:43:38.278+0000] {taskinstance.py:2905} ERROR - Task failed with exception
Traceback (most recent call last):
  File "/home/airflow/.local/lib/python3.12/site-packages/airflow/models/taskinstance.py", line 465, in _execute_task
    result = _execute_callable(context=context, **execute_callable_kwargs)
             ^^^^^^^^^^^^^^^^^^^^^^^^^^^^^^^^^^^^^^^^^^^^^^^^^^^^^^^^^^^^^
  File "/home/airflow/.local/lib/python3.12/site-packages/airflow/models/taskinstance.py", line 432, in _execute_callable
    return execute_callable(context=context, **execute_callable_kwargs)
           ^^^^^^^^^^^^^^^^^^^^^^^^^^^^^^^^^^^^^^^^^^^^^^^^^^^^^^^^^^^^
  File "/home/airflow/.local/lib/python3.12/site-packages/airflow/models/baseoperator.py", line 400, in wrapper
    return func(self, *args, **kwargs)
           ^^^^^^^^^^^^^^^^^^^^^^^^^^^
  File "/home/airflow/.local/lib/python3.12/site-packages/airflow/operators/python.py", line 235, in execute
    return_value = self.execute_callable()
                   ^^^^^^^^^^^^^^^^^^^^^^^
  File "/home/airflow/.local/lib/python3.12/site-packages/airflow/operators/python.py", line 252, in execute_callable
    return self.python_callable(*self.op_args, **self.op_kwargs)
           ^^^^^^^^^^^^^^^^^^^^^^^^^^^^^^^^^^^^^^^^^^^^^^^^^^^^^
  File "/opt/airflow/dags/bank_data_pipeline.py", line 102, in generate_banking_data
    raise AirflowException(error_msg)
airflow.exceptions.AirflowException: Data generation failed: Traceback (most recent call last):
  File "/opt/***/src/generate_data_***.py", line 8, in <module>
    from faker import Faker
ModuleNotFoundError: No module named 'faker'

[2025-07-16T16:43:38.285+0000] {taskinstance.py:1206} INFO - Marking task as UP_FOR_RETRY. dag_id=bank_data_pipeline, task_id=generate_banking_data, run_id=scheduled__2025-07-15T00:00:00+00:00, execution_date=20250715T000000, start_date=20250716T164337, end_date=20250716T164338
[2025-07-16T16:43:38.300+0000] {standard_task_runner.py:110} ERROR - Failed to execute job 4 for task generate_banking_data (Data generation failed: Traceback (most recent call last):
  File "/opt/***/src/generate_data_***.py", line 8, in <module>
    from faker import Faker
ModuleNotFoundError: No module named 'faker'
; 401)
[2025-07-16T16:43:38.347+0000] {local_task_job_runner.py:240} INFO - Task exited with return code 1
[2025-07-16T16:43:38.400+0000] {taskinstance.py:3498} INFO - 0 downstream tasks scheduled from follow-on schedule check
[2025-07-16T16:43:38.402+0000] {local_task_job_runner.py:222} INFO - ::endgroup::
[2025-07-16T16:46:30.734+0000] {local_task_job_runner.py:120} INFO - ::group::Pre task execution logs
[2025-07-16T16:46:30.771+0000] {taskinstance.py:2076} INFO - Dependencies all met for dep_context=non-requeueable deps ti=<TaskInstance: bank_data_pipeline.generate_banking_data scheduled__2025-07-15T00:00:00+00:00 [queued]>
[2025-07-16T16:46:30.780+0000] {taskinstance.py:2076} INFO - Dependencies all met for dep_context=requeueable deps ti=<TaskInstance: bank_data_pipeline.generate_banking_data scheduled__2025-07-15T00:00:00+00:00 [queued]>
[2025-07-16T16:46:30.780+0000] {taskinstance.py:2306} INFO - Starting attempt 1 of 3
[2025-07-16T16:46:30.791+0000] {taskinstance.py:2330} INFO - Executing <Task(PythonOperator): generate_banking_data> on 2025-07-15 00:00:00+00:00
[2025-07-16T16:46:30.798+0000] {logging_mixin.py:188} WARNING - /home/***/.local/lib/python3.12/site-packages/***/task/task_runner/standard_task_runner.py:61 DeprecationWarning: This process (pid=221) is multi-threaded, use of fork() may lead to deadlocks in the child.
[2025-07-16T16:46:30.799+0000] {standard_task_runner.py:63} INFO - Started process 222 to run task
[2025-07-16T16:46:30.802+0000] {standard_task_runner.py:90} INFO - Running: ['***', 'tasks', 'run', 'bank_data_pipeline', 'generate_banking_data', 'scheduled__2025-07-15T00:00:00+00:00', '--job-id', '4', '--raw', '--subdir', 'DAGS_FOLDER/bank_data_pipeline.py', '--cfg-path', '/tmp/tmpk_l0e3k1']
[2025-07-16T16:46:30.805+0000] {standard_task_runner.py:91} INFO - Job 4: Subtask generate_banking_data
[2025-07-16T16:46:30.821+0000] {logging_mixin.py:188} WARNING - /home/***/.local/lib/python3.12/site-packages/***/settings.py:195 DeprecationWarning: The sql_alchemy_conn option in [core] has been moved to the sql_alchemy_conn option in [database] - the old setting has been used, but please update your config.
[2025-07-16T16:46:30.863+0000] {task_command.py:426} INFO - Running <TaskInstance: bank_data_pipeline.generate_banking_data scheduled__2025-07-15T00:00:00+00:00 [running]> on host f8c2cd69d5df
[2025-07-16T16:46:30.959+0000] {taskinstance.py:2648} INFO - Exporting env vars: AIRFLOW_CTX_DAG_OWNER='data_engineering_team' AIRFLOW_CTX_DAG_ID='bank_data_pipeline' AIRFLOW_CTX_TASK_ID='generate_banking_data' AIRFLOW_CTX_EXECUTION_DATE='2025-07-15T00:00:00+00:00' AIRFLOW_CTX_TRY_NUMBER='1' AIRFLOW_CTX_DAG_RUN_ID='scheduled__2025-07-15T00:00:00+00:00'
[2025-07-16T16:46:30.960+0000] {taskinstance.py:430} INFO - ::endgroup::
[2025-07-16T16:46:30.971+0000] {logging_mixin.py:188} INFO - 2025-07-16 16:46:30,971 - pipeline_logger - INFO - Starting data generation for run scheduled__2025-07-15T00:00:00+00:00
[2025-07-16T16:46:30.971+0000] {pipeline_logger.py:224} INFO - Starting data generation for run scheduled__2025-07-15T00:00:00+00:00
[2025-07-16T16:46:31.155+0000] {logging_mixin.py:188} INFO - 2025-07-16 16:46:31,155 - pipeline_logger - ERROR - Pipeline error in generate_banking_data: Data generation failed: Traceback (most recent call last):
  File "/opt/***/src/generate_data_***.py", line 8, in <module>
    from faker import Faker
ModuleNotFoundError: No module named 'faker'
[2025-07-16T16:46:31.155+0000] {pipeline_logger.py:194} ERROR - Pipeline error in generate_banking_data: Data generation failed: Traceback (most recent call last):
  File "/opt/***/src/generate_data_***.py", line 8, in <module>
    from faker import Faker
ModuleNotFoundError: No module named 'faker'

[2025-07-16T16:46:31.168+0000] {logging_mixin.py:188} INFO - 2025-07-16 16:46:31,168 - pipeline_logger - ERROR - Pipeline error in generate_banking_data: Unexpected error in data generation: Data generation failed: Traceback (most recent call last):
  File "/opt/***/src/generate_data_***.py", line 8, in <module>
    from faker import Faker
ModuleNotFoundError: No module named 'faker'
[2025-07-16T16:46:31.168+0000] {pipeline_logger.py:194} ERROR - Pipeline error in generate_banking_data: Unexpected error in data generation: Data generation failed: Traceback (most recent call last):
  File "/opt/***/src/generate_data_***.py", line 8, in <module>
    from faker import Faker
ModuleNotFoundError: No module named 'faker'

[2025-07-16T16:46:31.169+0000] {taskinstance.py:441} INFO - ::group::Post task execution logs
[2025-07-16T16:46:31.190+0000] {taskinstance.py:2905} ERROR - Task failed with exception
Traceback (most recent call last):
  File "/home/airflow/.local/lib/python3.12/site-packages/airflow/models/taskinstance.py", line 465, in _execute_task
    result = _execute_callable(context=context, **execute_callable_kwargs)
             ^^^^^^^^^^^^^^^^^^^^^^^^^^^^^^^^^^^^^^^^^^^^^^^^^^^^^^^^^^^^^
  File "/home/airflow/.local/lib/python3.12/site-packages/airflow/models/taskinstance.py", line 432, in _execute_callable
    return execute_callable(context=context, **execute_callable_kwargs)
           ^^^^^^^^^^^^^^^^^^^^^^^^^^^^^^^^^^^^^^^^^^^^^^^^^^^^^^^^^^^^
  File "/home/airflow/.local/lib/python3.12/site-packages/airflow/models/baseoperator.py", line 400, in wrapper
    return func(self, *args, **kwargs)
           ^^^^^^^^^^^^^^^^^^^^^^^^^^^
  File "/home/airflow/.local/lib/python3.12/site-packages/airflow/operators/python.py", line 235, in execute
    return_value = self.execute_callable()
                   ^^^^^^^^^^^^^^^^^^^^^^^
  File "/home/airflow/.local/lib/python3.12/site-packages/airflow/operators/python.py", line 252, in execute_callable
    return self.python_callable(*self.op_args, **self.op_kwargs)
           ^^^^^^^^^^^^^^^^^^^^^^^^^^^^^^^^^^^^^^^^^^^^^^^^^^^^^
  File "/opt/airflow/dags/bank_data_pipeline.py", line 102, in generate_banking_data
    raise AirflowException(error_msg)
airflow.exceptions.AirflowException: Data generation failed: Traceback (most recent call last):
  File "/opt/***/src/generate_data_***.py", line 8, in <module>
    from faker import Faker
ModuleNotFoundError: No module named 'faker'

[2025-07-16T16:46:31.197+0000] {taskinstance.py:1206} INFO - Marking task as UP_FOR_RETRY. dag_id=bank_data_pipeline, task_id=generate_banking_data, run_id=scheduled__2025-07-15T00:00:00+00:00, execution_date=20250715T000000, start_date=20250716T164630, end_date=20250716T164631
[2025-07-16T16:46:31.214+0000] {standard_task_runner.py:110} ERROR - Failed to execute job 4 for task generate_banking_data (Data generation failed: Traceback (most recent call last):
  File "/opt/***/src/generate_data_***.py", line 8, in <module>
    from faker import Faker
ModuleNotFoundError: No module named 'faker'
; 222)
[2025-07-16T16:46:31.254+0000] {local_task_job_runner.py:240} INFO - Task exited with return code 1
[2025-07-16T16:46:31.279+0000] {taskinstance.py:3498} INFO - 0 downstream tasks scheduled from follow-on schedule check
[2025-07-16T16:46:31.280+0000] {local_task_job_runner.py:222} INFO - ::endgroup::
[2025-07-16T16:51:36.835+0000] {local_task_job_runner.py:120} INFO - ::group::Pre task execution logs
[2025-07-16T16:51:36.870+0000] {taskinstance.py:2076} INFO - Dependencies all met for dep_context=non-requeueable deps ti=<TaskInstance: bank_data_pipeline.generate_banking_data scheduled__2025-07-15T00:00:00+00:00 [queued]>
[2025-07-16T16:51:36.878+0000] {taskinstance.py:2076} INFO - Dependencies all met for dep_context=requeueable deps ti=<TaskInstance: bank_data_pipeline.generate_banking_data scheduled__2025-07-15T00:00:00+00:00 [queued]>
[2025-07-16T16:51:36.878+0000] {taskinstance.py:2306} INFO - Starting attempt 1 of 3
[2025-07-16T16:51:36.891+0000] {taskinstance.py:2330} INFO - Executing <Task(PythonOperator): generate_banking_data> on 2025-07-15 00:00:00+00:00
[2025-07-16T16:51:36.898+0000] {standard_task_runner.py:63} INFO - Started process 269 to run task
[2025-07-16T16:51:36.903+0000] {standard_task_runner.py:90} INFO - Running: ['***', 'tasks', 'run', 'bank_data_pipeline', 'generate_banking_data', 'scheduled__2025-07-15T00:00:00+00:00', '--job-id', '4', '--raw', '--subdir', 'DAGS_FOLDER/bank_data_pipeline.py', '--cfg-path', '/tmp/tmpv6muqc5o']
[2025-07-16T16:51:36.906+0000] {standard_task_runner.py:91} INFO - Job 4: Subtask generate_banking_data
[2025-07-16T16:51:36.926+0000] {logging_mixin.py:188} WARNING - /home/***/.local/lib/python3.10/site-packages/***/settings.py:195 DeprecationWarning: The sql_alchemy_conn option in [core] has been moved to the sql_alchemy_conn option in [database] - the old setting has been used, but please update your config.
[2025-07-16T16:51:36.971+0000] {task_command.py:426} INFO - Running <TaskInstance: bank_data_pipeline.generate_banking_data scheduled__2025-07-15T00:00:00+00:00 [running]> on host 039da2dd7cbf
[2025-07-16T16:51:37.053+0000] {taskinstance.py:2648} INFO - Exporting env vars: AIRFLOW_CTX_DAG_OWNER='data_engineering_team' AIRFLOW_CTX_DAG_ID='bank_data_pipeline' AIRFLOW_CTX_TASK_ID='generate_banking_data' AIRFLOW_CTX_EXECUTION_DATE='2025-07-15T00:00:00+00:00' AIRFLOW_CTX_TRY_NUMBER='1' AIRFLOW_CTX_DAG_RUN_ID='scheduled__2025-07-15T00:00:00+00:00'
[2025-07-16T16:51:37.053+0000] {taskinstance.py:430} INFO - ::endgroup::
[2025-07-16T16:51:37.062+0000] {logging_mixin.py:188} INFO - 2025-07-16 16:51:37,062 - pipeline_logger - INFO - Starting data generation for run scheduled__2025-07-15T00:00:00+00:00
[2025-07-16T16:51:37.062+0000] {pipeline_logger.py:224} INFO - Starting data generation for run scheduled__2025-07-15T00:00:00+00:00
[2025-07-16T16:51:37.502+0000] {logging_mixin.py:188} INFO - 2025-07-16 16:51:37,502 - pipeline_logger - ERROR - Pipeline error in generate_banking_data: Data generation failed: 2025-07-16 16:51:37,455 - INFO - Starting data generation process...
2025-07-16 16:51:37,462 - INFO - Database connection established successfully
2025-07-16 16:51:37,465 - ERROR - Error creating tables: relation "customer" already exists

2025-07-16 16:51:37,465 - INFO - Generating 10 customers...
2025-07-16 16:51:37,466 - ERROR - Error inserting customer 1: current transaction is aborted, commands ignored until end of transaction block

2025-07-16 16:51:37,466 - ERROR - Error inserting customer 2: current transaction is aborted, commands ignored until end of transaction block

2025-07-16 16:51:37,467 - ERROR - Error inserting customer 3: current transaction is aborted, commands ignored until end of transaction block

2025-07-16 16:51:37,468 - ERROR - Error inserting customer 4: current transaction is aborted, commands ignored until end of transaction block

2025-07-16 16:51:37,468 - ERROR - Error inserting customer 5: current transaction is aborted, commands ignored until end of transaction block

2025-07-16 16:51:37,469 - ERROR - Error inserting customer 6: current transaction is aborted, commands ignored until end of transaction block

2025-07-16 16:51:37,470 - ERROR - Error inserting customer 7: current transaction is aborted, commands ignored until end of transaction block

2025-07-16 16:51:37,470 - ERROR - Error inserting customer 8: current transaction is aborted, commands ignored until end of transaction block

2025-07-16 16:51:37,471 - ERROR - Error inserting customer 9: current transaction is aborted, commands ignored until end of transaction block

2025-07-16 16:51:37,472 - ERROR - Error inserting customer 10: current transaction is aborted, commands ignored until end of transaction block

2025-07-16 16:51:37,472 - INFO - Successfully generated 0 customers
2025-07-16 16:51:37,472 - ERROR - ❌ Data generation failed: Failed to generate customers
2025-07-16 16:51:37,472 - ERROR - Fatal error in data generation: Failed to generate customers
[2025-07-16T16:51:37.502+0000] {pipeline_logger.py:194} ERROR - Pipeline error in generate_banking_data: Data generation failed: 2025-07-16 16:51:37,455 - INFO - Starting data generation process...
2025-07-16 16:51:37,462 - INFO - Database connection established successfully
2025-07-16 16:51:37,465 - ERROR - Error creating tables: relation "customer" already exists

2025-07-16 16:51:37,465 - INFO - Generating 10 customers...
2025-07-16 16:51:37,466 - ERROR - Error inserting customer 1: current transaction is aborted, commands ignored until end of transaction block

2025-07-16 16:51:37,466 - ERROR - Error inserting customer 2: current transaction is aborted, commands ignored until end of transaction block

2025-07-16 16:51:37,467 - ERROR - Error inserting customer 3: current transaction is aborted, commands ignored until end of transaction block

2025-07-16 16:51:37,468 - ERROR - Error inserting customer 4: current transaction is aborted, commands ignored until end of transaction block

2025-07-16 16:51:37,468 - ERROR - Error inserting customer 5: current transaction is aborted, commands ignored until end of transaction block

2025-07-16 16:51:37,469 - ERROR - Error inserting customer 6: current transaction is aborted, commands ignored until end of transaction block

2025-07-16 16:51:37,470 - ERROR - Error inserting customer 7: current transaction is aborted, commands ignored until end of transaction block

2025-07-16 16:51:37,470 - ERROR - Error inserting customer 8: current transaction is aborted, commands ignored until end of transaction block

2025-07-16 16:51:37,471 - ERROR - Error inserting customer 9: current transaction is aborted, commands ignored until end of transaction block

2025-07-16 16:51:37,472 - ERROR - Error inserting customer 10: current transaction is aborted, commands ignored until end of transaction block

2025-07-16 16:51:37,472 - INFO - Successfully generated 0 customers
2025-07-16 16:51:37,472 - ERROR - ❌ Data generation failed: Failed to generate customers
2025-07-16 16:51:37,472 - ERROR - Fatal error in data generation: Failed to generate customers

[2025-07-16T16:51:37.513+0000] {logging_mixin.py:188} INFO - 2025-07-16 16:51:37,513 - pipeline_logger - ERROR - Pipeline error in generate_banking_data: Unexpected error in data generation: Data generation failed: 2025-07-16 16:51:37,455 - INFO - Starting data generation process...
2025-07-16 16:51:37,462 - INFO - Database connection established successfully
2025-07-16 16:51:37,465 - ERROR - Error creating tables: relation "customer" already exists

2025-07-16 16:51:37,465 - INFO - Generating 10 customers...
2025-07-16 16:51:37,466 - ERROR - Error inserting customer 1: current transaction is aborted, commands ignored until end of transaction block

2025-07-16 16:51:37,466 - ERROR - Error inserting customer 2: current transaction is aborted, commands ignored until end of transaction block

2025-07-16 16:51:37,467 - ERROR - Error inserting customer 3: current transaction is aborted, commands ignored until end of transaction block

2025-07-16 16:51:37,468 - ERROR - Error inserting customer 4: current transaction is aborted, commands ignored until end of transaction block

2025-07-16 16:51:37,468 - ERROR - Error inserting customer 5: current transaction is aborted, commands ignored until end of transaction block

2025-07-16 16:51:37,469 - ERROR - Error inserting customer 6: current transaction is aborted, commands ignored until end of transaction block

2025-07-16 16:51:37,470 - ERROR - Error inserting customer 7: current transaction is aborted, commands ignored until end of transaction block

2025-07-16 16:51:37,470 - ERROR - Error inserting customer 8: current transaction is aborted, commands ignored until end of transaction block

2025-07-16 16:51:37,471 - ERROR - Error inserting customer 9: current transaction is aborted, commands ignored until end of transaction block

2025-07-16 16:51:37,472 - ERROR - Error inserting customer 10: current transaction is aborted, commands ignored until end of transaction block

2025-07-16 16:51:37,472 - INFO - Successfully generated 0 customers
2025-07-16 16:51:37,472 - ERROR - ❌ Data generation failed: Failed to generate customers
2025-07-16 16:51:37,472 - ERROR - Fatal error in data generation: Failed to generate customers
[2025-07-16T16:51:37.513+0000] {pipeline_logger.py:194} ERROR - Pipeline error in generate_banking_data: Unexpected error in data generation: Data generation failed: 2025-07-16 16:51:37,455 - INFO - Starting data generation process...
2025-07-16 16:51:37,462 - INFO - Database connection established successfully
2025-07-16 16:51:37,465 - ERROR - Error creating tables: relation "customer" already exists

2025-07-16 16:51:37,465 - INFO - Generating 10 customers...
2025-07-16 16:51:37,466 - ERROR - Error inserting customer 1: current transaction is aborted, commands ignored until end of transaction block

2025-07-16 16:51:37,466 - ERROR - Error inserting customer 2: current transaction is aborted, commands ignored until end of transaction block

2025-07-16 16:51:37,467 - ERROR - Error inserting customer 3: current transaction is aborted, commands ignored until end of transaction block

2025-07-16 16:51:37,468 - ERROR - Error inserting customer 4: current transaction is aborted, commands ignored until end of transaction block

2025-07-16 16:51:37,468 - ERROR - Error inserting customer 5: current transaction is aborted, commands ignored until end of transaction block

2025-07-16 16:51:37,469 - ERROR - Error inserting customer 6: current transaction is aborted, commands ignored until end of transaction block

2025-07-16 16:51:37,470 - ERROR - Error inserting customer 7: current transaction is aborted, commands ignored until end of transaction block

2025-07-16 16:51:37,470 - ERROR - Error inserting customer 8: current transaction is aborted, commands ignored until end of transaction block

2025-07-16 16:51:37,471 - ERROR - Error inserting customer 9: current transaction is aborted, commands ignored until end of transaction block

2025-07-16 16:51:37,472 - ERROR - Error inserting customer 10: current transaction is aborted, commands ignored until end of transaction block

2025-07-16 16:51:37,472 - INFO - Successfully generated 0 customers
2025-07-16 16:51:37,472 - ERROR - ❌ Data generation failed: Failed to generate customers
2025-07-16 16:51:37,472 - ERROR - Fatal error in data generation: Failed to generate customers

[2025-07-16T16:51:37.513+0000] {taskinstance.py:441} INFO - ::group::Post task execution logs
[2025-07-16T16:51:37.531+0000] {taskinstance.py:2905} ERROR - Task failed with exception
Traceback (most recent call last):
  File "/home/airflow/.local/lib/python3.10/site-packages/airflow/models/taskinstance.py", line 465, in _execute_task
    result = _execute_callable(context=context, **execute_callable_kwargs)
  File "/home/airflow/.local/lib/python3.10/site-packages/airflow/models/taskinstance.py", line 432, in _execute_callable
    return execute_callable(context=context, **execute_callable_kwargs)
  File "/home/airflow/.local/lib/python3.10/site-packages/airflow/models/baseoperator.py", line 400, in wrapper
    return func(self, *args, **kwargs)
  File "/home/airflow/.local/lib/python3.10/site-packages/airflow/operators/python.py", line 235, in execute
    return_value = self.execute_callable()
  File "/home/airflow/.local/lib/python3.10/site-packages/airflow/operators/python.py", line 252, in execute_callable
    return self.python_callable(*self.op_args, **self.op_kwargs)
  File "/opt/airflow/dags/bank_data_pipeline.py", line 102, in generate_banking_data
    raise AirflowException(error_msg)
airflow.exceptions.AirflowException: Data generation failed: 2025-07-16 16:51:37,455 - INFO - Starting data generation process...
2025-07-16 16:51:37,462 - INFO - Database connection established successfully
2025-07-16 16:51:37,465 - ERROR - Error creating tables: relation "customer" already exists

2025-07-16 16:51:37,465 - INFO - Generating 10 customers...
2025-07-16 16:51:37,466 - ERROR - Error inserting customer 1: current transaction is aborted, commands ignored until end of transaction block

2025-07-16 16:51:37,466 - ERROR - Error inserting customer 2: current transaction is aborted, commands ignored until end of transaction block

2025-07-16 16:51:37,467 - ERROR - Error inserting customer 3: current transaction is aborted, commands ignored until end of transaction block

2025-07-16 16:51:37,468 - ERROR - Error inserting customer 4: current transaction is aborted, commands ignored until end of transaction block

2025-07-16 16:51:37,468 - ERROR - Error inserting customer 5: current transaction is aborted, commands ignored until end of transaction block

2025-07-16 16:51:37,469 - ERROR - Error inserting customer 6: current transaction is aborted, commands ignored until end of transaction block

2025-07-16 16:51:37,470 - ERROR - Error inserting customer 7: current transaction is aborted, commands ignored until end of transaction block

2025-07-16 16:51:37,470 - ERROR - Error inserting customer 8: current transaction is aborted, commands ignored until end of transaction block

2025-07-16 16:51:37,471 - ERROR - Error inserting customer 9: current transaction is aborted, commands ignored until end of transaction block

2025-07-16 16:51:37,472 - ERROR - Error inserting customer 10: current transaction is aborted, commands ignored until end of transaction block

2025-07-16 16:51:37,472 - INFO - Successfully generated 0 customers
2025-07-16 16:51:37,472 - ERROR - ❌ Data generation failed: Failed to generate customers
2025-07-16 16:51:37,472 - ERROR - Fatal error in data generation: Failed to generate customers

[2025-07-16T16:51:37.537+0000] {taskinstance.py:1206} INFO - Marking task as UP_FOR_RETRY. dag_id=bank_data_pipeline, task_id=generate_banking_data, run_id=scheduled__2025-07-15T00:00:00+00:00, execution_date=20250715T000000, start_date=20250716T165136, end_date=20250716T165137
[2025-07-16T16:51:37.558+0000] {standard_task_runner.py:110} ERROR - Failed to execute job 4 for task generate_banking_data (Data generation failed: 2025-07-16 16:51:37,455 - INFO - Starting data generation process...
2025-07-16 16:51:37,462 - INFO - Database connection established successfully
2025-07-16 16:51:37,465 - ERROR - Error creating tables: relation "customer" already exists

2025-07-16 16:51:37,465 - INFO - Generating 10 customers...
2025-07-16 16:51:37,466 - ERROR - Error inserting customer 1: current transaction is aborted, commands ignored until end of transaction block

2025-07-16 16:51:37,466 - ERROR - Error inserting customer 2: current transaction is aborted, commands ignored until end of transaction block

2025-07-16 16:51:37,467 - ERROR - Error inserting customer 3: current transaction is aborted, commands ignored until end of transaction block

2025-07-16 16:51:37,468 - ERROR - Error inserting customer 4: current transaction is aborted, commands ignored until end of transaction block

2025-07-16 16:51:37,468 - ERROR - Error inserting customer 5: current transaction is aborted, commands ignored until end of transaction block

2025-07-16 16:51:37,469 - ERROR - Error inserting customer 6: current transaction is aborted, commands ignored until end of transaction block

2025-07-16 16:51:37,470 - ERROR - Error inserting customer 7: current transaction is aborted, commands ignored until end of transaction block

2025-07-16 16:51:37,470 - ERROR - Error inserting customer 8: current transaction is aborted, commands ignored until end of transaction block

2025-07-16 16:51:37,471 - ERROR - Error inserting customer 9: current transaction is aborted, commands ignored until end of transaction block

2025-07-16 16:51:37,472 - ERROR - Error inserting customer 10: current transaction is aborted, commands ignored until end of transaction block

2025-07-16 16:51:37,472 - INFO - Successfully generated 0 customers
2025-07-16 16:51:37,472 - ERROR - ❌ Data generation failed: Failed to generate customers
2025-07-16 16:51:37,472 - ERROR - Fatal error in data generation: Failed to generate customers
; 269)
[2025-07-16T16:51:37.595+0000] {local_task_job_runner.py:240} INFO - Task exited with return code 1
[2025-07-16T16:51:37.628+0000] {taskinstance.py:3498} INFO - 0 downstream tasks scheduled from follow-on schedule check
[2025-07-16T16:51:37.629+0000] {local_task_job_runner.py:222} INFO - ::endgroup::
[2025-07-16T16:57:38.001+0000] {local_task_job_runner.py:120} INFO - ::group::Pre task execution logs
[2025-07-16T16:57:38.029+0000] {taskinstance.py:2076} INFO - Dependencies all met for dep_context=non-requeueable deps ti=<TaskInstance: bank_data_pipeline.generate_banking_data scheduled__2025-07-15T00:00:00+00:00 [queued]>
[2025-07-16T16:57:38.037+0000] {taskinstance.py:2076} INFO - Dependencies all met for dep_context=requeueable deps ti=<TaskInstance: bank_data_pipeline.generate_banking_data scheduled__2025-07-15T00:00:00+00:00 [queued]>
[2025-07-16T16:57:38.037+0000] {taskinstance.py:2306} INFO - Starting attempt 1 of 3
[2025-07-16T16:57:38.046+0000] {taskinstance.py:2330} INFO - Executing <Task(PythonOperator): generate_banking_data> on 2025-07-15 00:00:00+00:00
[2025-07-16T16:57:38.051+0000] {standard_task_runner.py:63} INFO - Started process 222 to run task
[2025-07-16T16:57:38.056+0000] {standard_task_runner.py:90} INFO - Running: ['***', 'tasks', 'run', 'bank_data_pipeline', 'generate_banking_data', 'scheduled__2025-07-15T00:00:00+00:00', '--job-id', '4', '--raw', '--subdir', 'DAGS_FOLDER/bank_data_pipeline.py', '--cfg-path', '/tmp/tmp1fjih7dl']
[2025-07-16T16:57:38.059+0000] {standard_task_runner.py:91} INFO - Job 4: Subtask generate_banking_data
[2025-07-16T16:57:38.079+0000] {logging_mixin.py:188} WARNING - /home/***/.local/lib/python3.10/site-packages/***/settings.py:195 DeprecationWarning: The sql_alchemy_conn option in [core] has been moved to the sql_alchemy_conn option in [database] - the old setting has been used, but please update your config.
[2025-07-16T16:57:38.114+0000] {task_command.py:426} INFO - Running <TaskInstance: bank_data_pipeline.generate_banking_data scheduled__2025-07-15T00:00:00+00:00 [running]> on host 130d0664bbcb
[2025-07-16T16:57:38.192+0000] {taskinstance.py:2648} INFO - Exporting env vars: AIRFLOW_CTX_DAG_OWNER='data_engineering_team' AIRFLOW_CTX_DAG_ID='bank_data_pipeline' AIRFLOW_CTX_TASK_ID='generate_banking_data' AIRFLOW_CTX_EXECUTION_DATE='2025-07-15T00:00:00+00:00' AIRFLOW_CTX_TRY_NUMBER='1' AIRFLOW_CTX_DAG_RUN_ID='scheduled__2025-07-15T00:00:00+00:00'
[2025-07-16T16:57:38.193+0000] {taskinstance.py:430} INFO - ::endgroup::
[2025-07-16T16:57:38.205+0000] {logging_mixin.py:188} INFO - 2025-07-16 16:57:38,205 - pipeline_logger - INFO - Starting data generation for run scheduled__2025-07-15T00:00:00+00:00
[2025-07-16T16:57:38.205+0000] {pipeline_logger.py:224} INFO - Starting data generation for run scheduled__2025-07-15T00:00:00+00:00
[2025-07-16T16:57:38.722+0000] {logging_mixin.py:188} INFO - 2025-07-16 16:57:38,722 - pipeline_logger - ERROR - Pipeline error in generate_banking_data: Data generation failed: 2025-07-16 16:57:38,669 - INFO - Starting data generation process...
2025-07-16 16:57:38,676 - INFO - Database connection established successfully
2025-07-16 16:57:38,678 - ERROR - Error creating tables: relation "customer" already exists

2025-07-16 16:57:38,678 - INFO - Generating 10 customers...
2025-07-16 16:57:38,681 - ERROR - Error inserting customer 1: current transaction is aborted, commands ignored until end of transaction block

2025-07-16 16:57:38,682 - ERROR - Error inserting customer 2: current transaction is aborted, commands ignored until end of transaction block

2025-07-16 16:57:38,683 - ERROR - Error inserting customer 3: current transaction is aborted, commands ignored until end of transaction block

2025-07-16 16:57:38,683 - ERROR - Error inserting customer 4: current transaction is aborted, commands ignored until end of transaction block

2025-07-16 16:57:38,684 - ERROR - Error inserting customer 5: current transaction is aborted, commands ignored until end of transaction block

2025-07-16 16:57:38,684 - ERROR - Error inserting customer 6: current transaction is aborted, commands ignored until end of transaction block

2025-07-16 16:57:38,685 - ERROR - Error inserting customer 7: current transaction is aborted, commands ignored until end of transaction block

2025-07-16 16:57:38,686 - ERROR - Error inserting customer 8: current transaction is aborted, commands ignored until end of transaction block

2025-07-16 16:57:38,687 - ERROR - Error inserting customer 9: current transaction is aborted, commands ignored until end of transaction block

2025-07-16 16:57:38,687 - ERROR - Error inserting customer 10: current transaction is aborted, commands ignored until end of transaction block

2025-07-16 16:57:38,688 - INFO - Successfully generated 0 customers
2025-07-16 16:57:38,688 - ERROR - ❌ Data generation failed: Failed to generate customers
2025-07-16 16:57:38,688 - ERROR - Fatal error in data generation: Failed to generate customers
[2025-07-16T16:57:38.722+0000] {pipeline_logger.py:194} ERROR - Pipeline error in generate_banking_data: Data generation failed: 2025-07-16 16:57:38,669 - INFO - Starting data generation process...
2025-07-16 16:57:38,676 - INFO - Database connection established successfully
2025-07-16 16:57:38,678 - ERROR - Error creating tables: relation "customer" already exists

2025-07-16 16:57:38,678 - INFO - Generating 10 customers...
2025-07-16 16:57:38,681 - ERROR - Error inserting customer 1: current transaction is aborted, commands ignored until end of transaction block

2025-07-16 16:57:38,682 - ERROR - Error inserting customer 2: current transaction is aborted, commands ignored until end of transaction block

2025-07-16 16:57:38,683 - ERROR - Error inserting customer 3: current transaction is aborted, commands ignored until end of transaction block

2025-07-16 16:57:38,683 - ERROR - Error inserting customer 4: current transaction is aborted, commands ignored until end of transaction block

2025-07-16 16:57:38,684 - ERROR - Error inserting customer 5: current transaction is aborted, commands ignored until end of transaction block

2025-07-16 16:57:38,684 - ERROR - Error inserting customer 6: current transaction is aborted, commands ignored until end of transaction block

2025-07-16 16:57:38,685 - ERROR - Error inserting customer 7: current transaction is aborted, commands ignored until end of transaction block

2025-07-16 16:57:38,686 - ERROR - Error inserting customer 8: current transaction is aborted, commands ignored until end of transaction block

2025-07-16 16:57:38,687 - ERROR - Error inserting customer 9: current transaction is aborted, commands ignored until end of transaction block

2025-07-16 16:57:38,687 - ERROR - Error inserting customer 10: current transaction is aborted, commands ignored until end of transaction block

2025-07-16 16:57:38,688 - INFO - Successfully generated 0 customers
2025-07-16 16:57:38,688 - ERROR - ❌ Data generation failed: Failed to generate customers
2025-07-16 16:57:38,688 - ERROR - Fatal error in data generation: Failed to generate customers

[2025-07-16T16:57:38.733+0000] {logging_mixin.py:188} INFO - 2025-07-16 16:57:38,733 - pipeline_logger - ERROR - Pipeline error in generate_banking_data: Unexpected error in data generation: Data generation failed: 2025-07-16 16:57:38,669 - INFO - Starting data generation process...
2025-07-16 16:57:38,676 - INFO - Database connection established successfully
2025-07-16 16:57:38,678 - ERROR - Error creating tables: relation "customer" already exists

2025-07-16 16:57:38,678 - INFO - Generating 10 customers...
2025-07-16 16:57:38,681 - ERROR - Error inserting customer 1: current transaction is aborted, commands ignored until end of transaction block

2025-07-16 16:57:38,682 - ERROR - Error inserting customer 2: current transaction is aborted, commands ignored until end of transaction block

2025-07-16 16:57:38,683 - ERROR - Error inserting customer 3: current transaction is aborted, commands ignored until end of transaction block

2025-07-16 16:57:38,683 - ERROR - Error inserting customer 4: current transaction is aborted, commands ignored until end of transaction block

2025-07-16 16:57:38,684 - ERROR - Error inserting customer 5: current transaction is aborted, commands ignored until end of transaction block

2025-07-16 16:57:38,684 - ERROR - Error inserting customer 6: current transaction is aborted, commands ignored until end of transaction block

2025-07-16 16:57:38,685 - ERROR - Error inserting customer 7: current transaction is aborted, commands ignored until end of transaction block

2025-07-16 16:57:38,686 - ERROR - Error inserting customer 8: current transaction is aborted, commands ignored until end of transaction block

2025-07-16 16:57:38,687 - ERROR - Error inserting customer 9: current transaction is aborted, commands ignored until end of transaction block

2025-07-16 16:57:38,687 - ERROR - Error inserting customer 10: current transaction is aborted, commands ignored until end of transaction block

2025-07-16 16:57:38,688 - INFO - Successfully generated 0 customers
2025-07-16 16:57:38,688 - ERROR - ❌ Data generation failed: Failed to generate customers
2025-07-16 16:57:38,688 - ERROR - Fatal error in data generation: Failed to generate customers
[2025-07-16T16:57:38.733+0000] {pipeline_logger.py:194} ERROR - Pipeline error in generate_banking_data: Unexpected error in data generation: Data generation failed: 2025-07-16 16:57:38,669 - INFO - Starting data generation process...
2025-07-16 16:57:38,676 - INFO - Database connection established successfully
2025-07-16 16:57:38,678 - ERROR - Error creating tables: relation "customer" already exists

2025-07-16 16:57:38,678 - INFO - Generating 10 customers...
2025-07-16 16:57:38,681 - ERROR - Error inserting customer 1: current transaction is aborted, commands ignored until end of transaction block

2025-07-16 16:57:38,682 - ERROR - Error inserting customer 2: current transaction is aborted, commands ignored until end of transaction block

2025-07-16 16:57:38,683 - ERROR - Error inserting customer 3: current transaction is aborted, commands ignored until end of transaction block

2025-07-16 16:57:38,683 - ERROR - Error inserting customer 4: current transaction is aborted, commands ignored until end of transaction block

2025-07-16 16:57:38,684 - ERROR - Error inserting customer 5: current transaction is aborted, commands ignored until end of transaction block

2025-07-16 16:57:38,684 - ERROR - Error inserting customer 6: current transaction is aborted, commands ignored until end of transaction block

2025-07-16 16:57:38,685 - ERROR - Error inserting customer 7: current transaction is aborted, commands ignored until end of transaction block

2025-07-16 16:57:38,686 - ERROR - Error inserting customer 8: current transaction is aborted, commands ignored until end of transaction block

2025-07-16 16:57:38,687 - ERROR - Error inserting customer 9: current transaction is aborted, commands ignored until end of transaction block

2025-07-16 16:57:38,687 - ERROR - Error inserting customer 10: current transaction is aborted, commands ignored until end of transaction block

2025-07-16 16:57:38,688 - INFO - Successfully generated 0 customers
2025-07-16 16:57:38,688 - ERROR - ❌ Data generation failed: Failed to generate customers
2025-07-16 16:57:38,688 - ERROR - Fatal error in data generation: Failed to generate customers

[2025-07-16T16:57:38.734+0000] {taskinstance.py:441} INFO - ::group::Post task execution logs
[2025-07-16T16:57:38.745+0000] {taskinstance.py:2905} ERROR - Task failed with exception
Traceback (most recent call last):
  File "/home/airflow/.local/lib/python3.10/site-packages/airflow/models/taskinstance.py", line 465, in _execute_task
    result = _execute_callable(context=context, **execute_callable_kwargs)
  File "/home/airflow/.local/lib/python3.10/site-packages/airflow/models/taskinstance.py", line 432, in _execute_callable
    return execute_callable(context=context, **execute_callable_kwargs)
  File "/home/airflow/.local/lib/python3.10/site-packages/airflow/models/baseoperator.py", line 400, in wrapper
    return func(self, *args, **kwargs)
  File "/home/airflow/.local/lib/python3.10/site-packages/airflow/operators/python.py", line 235, in execute
    return_value = self.execute_callable()
  File "/home/airflow/.local/lib/python3.10/site-packages/airflow/operators/python.py", line 252, in execute_callable
    return self.python_callable(*self.op_args, **self.op_kwargs)
  File "/opt/airflow/dags/bank_data_pipeline.py", line 102, in generate_banking_data
    raise AirflowException(error_msg)
airflow.exceptions.AirflowException: Data generation failed: 2025-07-16 16:57:38,669 - INFO - Starting data generation process...
2025-07-16 16:57:38,676 - INFO - Database connection established successfully
2025-07-16 16:57:38,678 - ERROR - Error creating tables: relation "customer" already exists

2025-07-16 16:57:38,678 - INFO - Generating 10 customers...
2025-07-16 16:57:38,681 - ERROR - Error inserting customer 1: current transaction is aborted, commands ignored until end of transaction block

2025-07-16 16:57:38,682 - ERROR - Error inserting customer 2: current transaction is aborted, commands ignored until end of transaction block

2025-07-16 16:57:38,683 - ERROR - Error inserting customer 3: current transaction is aborted, commands ignored until end of transaction block

2025-07-16 16:57:38,683 - ERROR - Error inserting customer 4: current transaction is aborted, commands ignored until end of transaction block

2025-07-16 16:57:38,684 - ERROR - Error inserting customer 5: current transaction is aborted, commands ignored until end of transaction block

2025-07-16 16:57:38,684 - ERROR - Error inserting customer 6: current transaction is aborted, commands ignored until end of transaction block

2025-07-16 16:57:38,685 - ERROR - Error inserting customer 7: current transaction is aborted, commands ignored until end of transaction block

2025-07-16 16:57:38,686 - ERROR - Error inserting customer 8: current transaction is aborted, commands ignored until end of transaction block

2025-07-16 16:57:38,687 - ERROR - Error inserting customer 9: current transaction is aborted, commands ignored until end of transaction block

2025-07-16 16:57:38,687 - ERROR - Error inserting customer 10: current transaction is aborted, commands ignored until end of transaction block

2025-07-16 16:57:38,688 - INFO - Successfully generated 0 customers
2025-07-16 16:57:38,688 - ERROR - ❌ Data generation failed: Failed to generate customers
2025-07-16 16:57:38,688 - ERROR - Fatal error in data generation: Failed to generate customers

[2025-07-16T16:57:38.748+0000] {taskinstance.py:1206} INFO - Marking task as UP_FOR_RETRY. dag_id=bank_data_pipeline, task_id=generate_banking_data, run_id=scheduled__2025-07-15T00:00:00+00:00, execution_date=20250715T000000, start_date=20250716T165738, end_date=20250716T165738
[2025-07-16T16:57:38.757+0000] {standard_task_runner.py:110} ERROR - Failed to execute job 4 for task generate_banking_data (Data generation failed: 2025-07-16 16:57:38,669 - INFO - Starting data generation process...
2025-07-16 16:57:38,676 - INFO - Database connection established successfully
2025-07-16 16:57:38,678 - ERROR - Error creating tables: relation "customer" already exists

2025-07-16 16:57:38,678 - INFO - Generating 10 customers...
2025-07-16 16:57:38,681 - ERROR - Error inserting customer 1: current transaction is aborted, commands ignored until end of transaction block

2025-07-16 16:57:38,682 - ERROR - Error inserting customer 2: current transaction is aborted, commands ignored until end of transaction block

2025-07-16 16:57:38,683 - ERROR - Error inserting customer 3: current transaction is aborted, commands ignored until end of transaction block

2025-07-16 16:57:38,683 - ERROR - Error inserting customer 4: current transaction is aborted, commands ignored until end of transaction block

2025-07-16 16:57:38,684 - ERROR - Error inserting customer 5: current transaction is aborted, commands ignored until end of transaction block

2025-07-16 16:57:38,684 - ERROR - Error inserting customer 6: current transaction is aborted, commands ignored until end of transaction block

2025-07-16 16:57:38,685 - ERROR - Error inserting customer 7: current transaction is aborted, commands ignored until end of transaction block

2025-07-16 16:57:38,686 - ERROR - Error inserting customer 8: current transaction is aborted, commands ignored until end of transaction block

2025-07-16 16:57:38,687 - ERROR - Error inserting customer 9: current transaction is aborted, commands ignored until end of transaction block

2025-07-16 16:57:38,687 - ERROR - Error inserting customer 10: current transaction is aborted, commands ignored until end of transaction block

2025-07-16 16:57:38,688 - INFO - Successfully generated 0 customers
2025-07-16 16:57:38,688 - ERROR - ❌ Data generation failed: Failed to generate customers
2025-07-16 16:57:38,688 - ERROR - Fatal error in data generation: Failed to generate customers
; 222)
[2025-07-16T16:57:38.788+0000] {local_task_job_runner.py:240} INFO - Task exited with return code 1
[2025-07-16T16:57:38.828+0000] {taskinstance.py:3498} INFO - 0 downstream tasks scheduled from follow-on schedule check
[2025-07-16T16:57:38.829+0000] {local_task_job_runner.py:222} INFO - ::endgroup::
[2025-07-16T17:04:18.109+0000] {local_task_job_runner.py:120} INFO - ::group::Pre task execution logs
[2025-07-16T17:04:18.140+0000] {taskinstance.py:2076} INFO - Dependencies all met for dep_context=non-requeueable deps ti=<TaskInstance: bank_data_pipeline.generate_banking_data scheduled__2025-07-15T00:00:00+00:00 [queued]>
[2025-07-16T17:04:18.148+0000] {taskinstance.py:2076} INFO - Dependencies all met for dep_context=requeueable deps ti=<TaskInstance: bank_data_pipeline.generate_banking_data scheduled__2025-07-15T00:00:00+00:00 [queued]>
[2025-07-16T17:04:18.148+0000] {taskinstance.py:2306} INFO - Starting attempt 1 of 3
[2025-07-16T17:04:18.159+0000] {taskinstance.py:2330} INFO - Executing <Task(PythonOperator): generate_banking_data> on 2025-07-15 00:00:00+00:00
[2025-07-16T17:04:18.164+0000] {standard_task_runner.py:63} INFO - Started process 251 to run task
[2025-07-16T17:04:18.167+0000] {standard_task_runner.py:90} INFO - Running: ['***', 'tasks', 'run', 'bank_data_pipeline', 'generate_banking_data', 'scheduled__2025-07-15T00:00:00+00:00', '--job-id', '4', '--raw', '--subdir', 'DAGS_FOLDER/bank_data_pipeline.py', '--cfg-path', '/tmp/tmpkque3z4v']
[2025-07-16T17:04:18.169+0000] {standard_task_runner.py:91} INFO - Job 4: Subtask generate_banking_data
[2025-07-16T17:04:18.185+0000] {logging_mixin.py:188} WARNING - /home/***/.local/lib/python3.10/site-packages/***/settings.py:195 DeprecationWarning: The sql_alchemy_conn option in [core] has been moved to the sql_alchemy_conn option in [database] - the old setting has been used, but please update your config.
[2025-07-16T17:04:18.229+0000] {task_command.py:426} INFO - Running <TaskInstance: bank_data_pipeline.generate_banking_data scheduled__2025-07-15T00:00:00+00:00 [running]> on host 055183203c9b
[2025-07-16T17:04:18.318+0000] {taskinstance.py:2648} INFO - Exporting env vars: AIRFLOW_CTX_DAG_OWNER='data_engineering_team' AIRFLOW_CTX_DAG_ID='bank_data_pipeline' AIRFLOW_CTX_TASK_ID='generate_banking_data' AIRFLOW_CTX_EXECUTION_DATE='2025-07-15T00:00:00+00:00' AIRFLOW_CTX_TRY_NUMBER='1' AIRFLOW_CTX_DAG_RUN_ID='scheduled__2025-07-15T00:00:00+00:00'
[2025-07-16T17:04:18.319+0000] {taskinstance.py:430} INFO - ::endgroup::
[2025-07-16T17:04:18.332+0000] {logging_mixin.py:188} INFO - 2025-07-16 17:04:18,332 - pipeline_logger - INFO - Starting data generation for run scheduled__2025-07-15T00:00:00+00:00
[2025-07-16T17:04:18.332+0000] {pipeline_logger.py:224} INFO - Starting data generation for run scheduled__2025-07-15T00:00:00+00:00
[2025-07-16T17:04:18.794+0000] {logging_mixin.py:188} INFO - 2025-07-16 17:04:18,794 - pipeline_logger - ERROR - Pipeline error in generate_banking_data: Data generation failed: 2025-07-16 17:04:18,748 - INFO - Starting data generation process...
2025-07-16 17:04:18,754 - INFO - Database connection established successfully
2025-07-16 17:04:18,756 - ERROR - Error creating tables: relation "customer" already exists

2025-07-16 17:04:18,756 - INFO - Generating 10 customers...
2025-07-16 17:04:18,756 - ERROR - Error inserting customer 1: current transaction is aborted, commands ignored until end of transaction block

2025-07-16 17:04:18,757 - ERROR - Error inserting customer 2: current transaction is aborted, commands ignored until end of transaction block

2025-07-16 17:04:18,758 - ERROR - Error inserting customer 3: current transaction is aborted, commands ignored until end of transaction block

2025-07-16 17:04:18,759 - ERROR - Error inserting customer 4: current transaction is aborted, commands ignored until end of transaction block

2025-07-16 17:04:18,760 - ERROR - Error inserting customer 5: current transaction is aborted, commands ignored until end of transaction block

2025-07-16 17:04:18,761 - ERROR - Error inserting customer 6: current transaction is aborted, commands ignored until end of transaction block

2025-07-16 17:04:18,763 - ERROR - Error inserting customer 7: current transaction is aborted, commands ignored until end of transaction block

2025-07-16 17:04:18,763 - ERROR - Error inserting customer 8: current transaction is aborted, commands ignored until end of transaction block

2025-07-16 17:04:18,764 - ERROR - Error inserting customer 9: current transaction is aborted, commands ignored until end of transaction block

2025-07-16 17:04:18,765 - ERROR - Error inserting customer 10: current transaction is aborted, commands ignored until end of transaction block

2025-07-16 17:04:18,766 - INFO - Successfully generated 0 customers
2025-07-16 17:04:18,766 - ERROR - ❌ Data generation failed: Failed to generate customers
2025-07-16 17:04:18,766 - ERROR - Fatal error in data generation: Failed to generate customers
[2025-07-16T17:04:18.794+0000] {pipeline_logger.py:194} ERROR - Pipeline error in generate_banking_data: Data generation failed: 2025-07-16 17:04:18,748 - INFO - Starting data generation process...
2025-07-16 17:04:18,754 - INFO - Database connection established successfully
2025-07-16 17:04:18,756 - ERROR - Error creating tables: relation "customer" already exists

2025-07-16 17:04:18,756 - INFO - Generating 10 customers...
2025-07-16 17:04:18,756 - ERROR - Error inserting customer 1: current transaction is aborted, commands ignored until end of transaction block

2025-07-16 17:04:18,757 - ERROR - Error inserting customer 2: current transaction is aborted, commands ignored until end of transaction block

2025-07-16 17:04:18,758 - ERROR - Error inserting customer 3: current transaction is aborted, commands ignored until end of transaction block

2025-07-16 17:04:18,759 - ERROR - Error inserting customer 4: current transaction is aborted, commands ignored until end of transaction block

2025-07-16 17:04:18,760 - ERROR - Error inserting customer 5: current transaction is aborted, commands ignored until end of transaction block

2025-07-16 17:04:18,761 - ERROR - Error inserting customer 6: current transaction is aborted, commands ignored until end of transaction block

2025-07-16 17:04:18,763 - ERROR - Error inserting customer 7: current transaction is aborted, commands ignored until end of transaction block

2025-07-16 17:04:18,763 - ERROR - Error inserting customer 8: current transaction is aborted, commands ignored until end of transaction block

2025-07-16 17:04:18,764 - ERROR - Error inserting customer 9: current transaction is aborted, commands ignored until end of transaction block

2025-07-16 17:04:18,765 - ERROR - Error inserting customer 10: current transaction is aborted, commands ignored until end of transaction block

2025-07-16 17:04:18,766 - INFO - Successfully generated 0 customers
2025-07-16 17:04:18,766 - ERROR - ❌ Data generation failed: Failed to generate customers
2025-07-16 17:04:18,766 - ERROR - Fatal error in data generation: Failed to generate customers

[2025-07-16T17:04:18.804+0000] {logging_mixin.py:188} INFO - 2025-07-16 17:04:18,804 - pipeline_logger - ERROR - Pipeline error in generate_banking_data: Unexpected error in data generation: Data generation failed: 2025-07-16 17:04:18,748 - INFO - Starting data generation process...
2025-07-16 17:04:18,754 - INFO - Database connection established successfully
2025-07-16 17:04:18,756 - ERROR - Error creating tables: relation "customer" already exists

2025-07-16 17:04:18,756 - INFO - Generating 10 customers...
2025-07-16 17:04:18,756 - ERROR - Error inserting customer 1: current transaction is aborted, commands ignored until end of transaction block

2025-07-16 17:04:18,757 - ERROR - Error inserting customer 2: current transaction is aborted, commands ignored until end of transaction block

2025-07-16 17:04:18,758 - ERROR - Error inserting customer 3: current transaction is aborted, commands ignored until end of transaction block

2025-07-16 17:04:18,759 - ERROR - Error inserting customer 4: current transaction is aborted, commands ignored until end of transaction block

2025-07-16 17:04:18,760 - ERROR - Error inserting customer 5: current transaction is aborted, commands ignored until end of transaction block

2025-07-16 17:04:18,761 - ERROR - Error inserting customer 6: current transaction is aborted, commands ignored until end of transaction block

2025-07-16 17:04:18,763 - ERROR - Error inserting customer 7: current transaction is aborted, commands ignored until end of transaction block

2025-07-16 17:04:18,763 - ERROR - Error inserting customer 8: current transaction is aborted, commands ignored until end of transaction block

2025-07-16 17:04:18,764 - ERROR - Error inserting customer 9: current transaction is aborted, commands ignored until end of transaction block

2025-07-16 17:04:18,765 - ERROR - Error inserting customer 10: current transaction is aborted, commands ignored until end of transaction block

2025-07-16 17:04:18,766 - INFO - Successfully generated 0 customers
2025-07-16 17:04:18,766 - ERROR - ❌ Data generation failed: Failed to generate customers
2025-07-16 17:04:18,766 - ERROR - Fatal error in data generation: Failed to generate customers
[2025-07-16T17:04:18.804+0000] {pipeline_logger.py:194} ERROR - Pipeline error in generate_banking_data: Unexpected error in data generation: Data generation failed: 2025-07-16 17:04:18,748 - INFO - Starting data generation process...
2025-07-16 17:04:18,754 - INFO - Database connection established successfully
2025-07-16 17:04:18,756 - ERROR - Error creating tables: relation "customer" already exists

2025-07-16 17:04:18,756 - INFO - Generating 10 customers...
2025-07-16 17:04:18,756 - ERROR - Error inserting customer 1: current transaction is aborted, commands ignored until end of transaction block

2025-07-16 17:04:18,757 - ERROR - Error inserting customer 2: current transaction is aborted, commands ignored until end of transaction block

2025-07-16 17:04:18,758 - ERROR - Error inserting customer 3: current transaction is aborted, commands ignored until end of transaction block

2025-07-16 17:04:18,759 - ERROR - Error inserting customer 4: current transaction is aborted, commands ignored until end of transaction block

2025-07-16 17:04:18,760 - ERROR - Error inserting customer 5: current transaction is aborted, commands ignored until end of transaction block

2025-07-16 17:04:18,761 - ERROR - Error inserting customer 6: current transaction is aborted, commands ignored until end of transaction block

2025-07-16 17:04:18,763 - ERROR - Error inserting customer 7: current transaction is aborted, commands ignored until end of transaction block

2025-07-16 17:04:18,763 - ERROR - Error inserting customer 8: current transaction is aborted, commands ignored until end of transaction block

2025-07-16 17:04:18,764 - ERROR - Error inserting customer 9: current transaction is aborted, commands ignored until end of transaction block

2025-07-16 17:04:18,765 - ERROR - Error inserting customer 10: current transaction is aborted, commands ignored until end of transaction block

2025-07-16 17:04:18,766 - INFO - Successfully generated 0 customers
2025-07-16 17:04:18,766 - ERROR - ❌ Data generation failed: Failed to generate customers
2025-07-16 17:04:18,766 - ERROR - Fatal error in data generation: Failed to generate customers

[2025-07-16T17:04:18.805+0000] {taskinstance.py:441} INFO - ::group::Post task execution logs
[2025-07-16T17:04:18.814+0000] {taskinstance.py:2905} ERROR - Task failed with exception
Traceback (most recent call last):
  File "/home/airflow/.local/lib/python3.10/site-packages/airflow/models/taskinstance.py", line 465, in _execute_task
    result = _execute_callable(context=context, **execute_callable_kwargs)
  File "/home/airflow/.local/lib/python3.10/site-packages/airflow/models/taskinstance.py", line 432, in _execute_callable
    return execute_callable(context=context, **execute_callable_kwargs)
  File "/home/airflow/.local/lib/python3.10/site-packages/airflow/models/baseoperator.py", line 400, in wrapper
    return func(self, *args, **kwargs)
  File "/home/airflow/.local/lib/python3.10/site-packages/airflow/operators/python.py", line 235, in execute
    return_value = self.execute_callable()
  File "/home/airflow/.local/lib/python3.10/site-packages/airflow/operators/python.py", line 252, in execute_callable
    return self.python_callable(*self.op_args, **self.op_kwargs)
  File "/opt/airflow/dags/bank_data_pipeline.py", line 102, in generate_banking_data
    raise AirflowException(error_msg)
airflow.exceptions.AirflowException: Data generation failed: 2025-07-16 17:04:18,748 - INFO - Starting data generation process...
2025-07-16 17:04:18,754 - INFO - Database connection established successfully
2025-07-16 17:04:18,756 - ERROR - Error creating tables: relation "customer" already exists

2025-07-16 17:04:18,756 - INFO - Generating 10 customers...
2025-07-16 17:04:18,756 - ERROR - Error inserting customer 1: current transaction is aborted, commands ignored until end of transaction block

2025-07-16 17:04:18,757 - ERROR - Error inserting customer 2: current transaction is aborted, commands ignored until end of transaction block

2025-07-16 17:04:18,758 - ERROR - Error inserting customer 3: current transaction is aborted, commands ignored until end of transaction block

2025-07-16 17:04:18,759 - ERROR - Error inserting customer 4: current transaction is aborted, commands ignored until end of transaction block

2025-07-16 17:04:18,760 - ERROR - Error inserting customer 5: current transaction is aborted, commands ignored until end of transaction block

2025-07-16 17:04:18,761 - ERROR - Error inserting customer 6: current transaction is aborted, commands ignored until end of transaction block

2025-07-16 17:04:18,763 - ERROR - Error inserting customer 7: current transaction is aborted, commands ignored until end of transaction block

2025-07-16 17:04:18,763 - ERROR - Error inserting customer 8: current transaction is aborted, commands ignored until end of transaction block

2025-07-16 17:04:18,764 - ERROR - Error inserting customer 9: current transaction is aborted, commands ignored until end of transaction block

2025-07-16 17:04:18,765 - ERROR - Error inserting customer 10: current transaction is aborted, commands ignored until end of transaction block

2025-07-16 17:04:18,766 - INFO - Successfully generated 0 customers
2025-07-16 17:04:18,766 - ERROR - ❌ Data generation failed: Failed to generate customers
2025-07-16 17:04:18,766 - ERROR - Fatal error in data generation: Failed to generate customers

[2025-07-16T17:04:18.817+0000] {taskinstance.py:1206} INFO - Marking task as UP_FOR_RETRY. dag_id=bank_data_pipeline, task_id=generate_banking_data, run_id=scheduled__2025-07-15T00:00:00+00:00, execution_date=20250715T000000, start_date=20250716T170418, end_date=20250716T170418
[2025-07-16T17:04:18.828+0000] {standard_task_runner.py:110} ERROR - Failed to execute job 4 for task generate_banking_data (Data generation failed: 2025-07-16 17:04:18,748 - INFO - Starting data generation process...
2025-07-16 17:04:18,754 - INFO - Database connection established successfully
2025-07-16 17:04:18,756 - ERROR - Error creating tables: relation "customer" already exists

2025-07-16 17:04:18,756 - INFO - Generating 10 customers...
2025-07-16 17:04:18,756 - ERROR - Error inserting customer 1: current transaction is aborted, commands ignored until end of transaction block

2025-07-16 17:04:18,757 - ERROR - Error inserting customer 2: current transaction is aborted, commands ignored until end of transaction block

2025-07-16 17:04:18,758 - ERROR - Error inserting customer 3: current transaction is aborted, commands ignored until end of transaction block

2025-07-16 17:04:18,759 - ERROR - Error inserting customer 4: current transaction is aborted, commands ignored until end of transaction block

2025-07-16 17:04:18,760 - ERROR - Error inserting customer 5: current transaction is aborted, commands ignored until end of transaction block

2025-07-16 17:04:18,761 - ERROR - Error inserting customer 6: current transaction is aborted, commands ignored until end of transaction block

2025-07-16 17:04:18,763 - ERROR - Error inserting customer 7: current transaction is aborted, commands ignored until end of transaction block

2025-07-16 17:04:18,763 - ERROR - Error inserting customer 8: current transaction is aborted, commands ignored until end of transaction block

2025-07-16 17:04:18,764 - ERROR - Error inserting customer 9: current transaction is aborted, commands ignored until end of transaction block

2025-07-16 17:04:18,765 - ERROR - Error inserting customer 10: current transaction is aborted, commands ignored until end of transaction block

2025-07-16 17:04:18,766 - INFO - Successfully generated 0 customers
2025-07-16 17:04:18,766 - ERROR - ❌ Data generation failed: Failed to generate customers
2025-07-16 17:04:18,766 - ERROR - Fatal error in data generation: Failed to generate customers
; 251)
[2025-07-16T17:04:18.862+0000] {local_task_job_runner.py:240} INFO - Task exited with return code 1
[2025-07-16T17:04:18.911+0000] {taskinstance.py:3498} INFO - 0 downstream tasks scheduled from follow-on schedule check
[2025-07-16T17:04:18.913+0000] {local_task_job_runner.py:222} INFO - ::endgroup::
