[2025-07-16T15:25:38.200+0000] {local_task_job_runner.py:120} INFO - ::group::Pre task execution logs
[2025-07-16T15:25:38.255+0000] {taskinstance.py:2076} INFO - Dependencies all met for dep_context=non-requeueable deps ti=<TaskInstance: bank_data_pipeline.log_pipeline_failures manual__2025-07-16T15:19:01.457315+00:00 [queued]>
[2025-07-16T15:25:38.268+0000] {taskinstance.py:2076} INFO - Dependencies all met for dep_context=requeueable deps ti=<TaskInstance: bank_data_pipeline.log_pipeline_failures manual__2025-07-16T15:19:01.457315+00:00 [queued]>
[2025-07-16T15:25:38.269+0000] {taskinstance.py:2306} INFO - Starting attempt 1 of 3
[2025-07-16T15:25:38.284+0000] {taskinstance.py:2330} INFO - Executing <Task(PythonOperator): log_pipeline_failures> on 2025-07-16 15:19:01.457315+00:00
[2025-07-16T15:25:38.296+0000] {logging_mixin.py:188} WARNING - /home/***/.local/lib/python3.12/site-packages/***/task/task_runner/standard_task_runner.py:61 DeprecationWarning: This process (pid=614) is multi-threaded, use of fork() may lead to deadlocks in the child.
[2025-07-16T15:25:38.297+0000] {standard_task_runner.py:63} INFO - Started process 615 to run task
[2025-07-16T15:25:38.295+0000] {standard_task_runner.py:90} INFO - Running: ['***', 'tasks', 'run', 'bank_data_pipeline', 'log_pipeline_failures', 'manual__2025-07-16T15:19:01.457315+00:00', '--job-id', '7', '--raw', '--subdir', 'DAGS_FOLDER/bank_data_pipeline.py', '--cfg-path', '/tmp/tmp31eap41p']
[2025-07-16T15:25:38.297+0000] {standard_task_runner.py:91} INFO - Job 7: Subtask log_pipeline_failures
[2025-07-16T15:25:38.320+0000] {logging_mixin.py:188} WARNING - /home/***/.local/lib/python3.12/site-packages/***/settings.py:195 DeprecationWarning: The sql_alchemy_conn option in [core] has been moved to the sql_alchemy_conn option in [database] - the old setting has been used, but please update your config.
[2025-07-16T15:25:38.369+0000] {task_command.py:426} INFO - Running <TaskInstance: bank_data_pipeline.log_pipeline_failures manual__2025-07-16T15:19:01.457315+00:00 [running]> on host 4c2c441a4888
[2025-07-16T15:25:38.495+0000] {taskinstance.py:2648} INFO - Exporting env vars: AIRFLOW_CTX_DAG_OWNER='data_engineering_team' AIRFLOW_CTX_DAG_ID='bank_data_pipeline' AIRFLOW_CTX_TASK_ID='log_pipeline_failures' AIRFLOW_CTX_EXECUTION_DATE='2025-07-16T15:19:01.457315+00:00' AIRFLOW_CTX_TRY_NUMBER='1' AIRFLOW_CTX_DAG_RUN_ID='manual__2025-07-16T15:19:01.457315+00:00'
[2025-07-16T15:25:38.496+0000] {taskinstance.py:430} INFO - ::endgroup::
[2025-07-16T15:25:38.515+0000] {taskinstance.py:441} INFO - ::group::Post task execution logs
[2025-07-16T15:25:38.515+0000] {taskinstance.py:2905} ERROR - Task failed with exception
Traceback (most recent call last):
  File "/home/airflow/.local/lib/python3.12/site-packages/airflow/models/taskinstance.py", line 465, in _execute_task
    result = _execute_callable(context=context, **execute_callable_kwargs)
             ^^^^^^^^^^^^^^^^^^^^^^^^^^^^^^^^^^^^^^^^^^^^^^^^^^^^^^^^^^^^^
  File "/home/airflow/.local/lib/python3.12/site-packages/airflow/models/taskinstance.py", line 432, in _execute_callable
    return execute_callable(context=context, **execute_callable_kwargs)
           ^^^^^^^^^^^^^^^^^^^^^^^^^^^^^^^^^^^^^^^^^^^^^^^^^^^^^^^^^^^^
  File "/home/airflow/.local/lib/python3.12/site-packages/airflow/models/baseoperator.py", line 400, in wrapper
    return func(self, *args, **kwargs)
           ^^^^^^^^^^^^^^^^^^^^^^^^^^^
  File "/home/airflow/.local/lib/python3.12/site-packages/airflow/operators/python.py", line 235, in execute
    return_value = self.execute_callable()
                   ^^^^^^^^^^^^^^^^^^^^^^^
  File "/home/airflow/.local/lib/python3.12/site-packages/airflow/operators/python.py", line 252, in execute_callable
    return self.python_callable(*self.op_args, **self.op_kwargs)
           ^^^^^^^^^^^^^^^^^^^^^^^^^^^^^^^^^^^^^^^^^^^^^^^^^^^^^
  File "/opt/airflow/dags/bank_data_pipeline.py", line 202, in log_pipeline_failure
    logger = PipelineLogger()
             ^^^^^^^^^^^^^^
NameError: name 'PipelineLogger' is not defined
[2025-07-16T15:25:38.544+0000] {taskinstance.py:1206} INFO - Marking task as UP_FOR_RETRY. dag_id=bank_data_pipeline, task_id=log_pipeline_failures, run_id=manual__2025-07-16T15:19:01.457315+00:00, execution_date=20250716T151901, start_date=20250716T152538, end_date=20250716T152538
[2025-07-16T15:25:38.561+0000] {standard_task_runner.py:110} ERROR - Failed to execute job 7 for task log_pipeline_failures (name 'PipelineLogger' is not defined; 615)
[2025-07-16T15:25:38.591+0000] {local_task_job_runner.py:240} INFO - Task exited with return code 1
[2025-07-16T15:25:38.617+0000] {taskinstance.py:3498} INFO - 0 downstream tasks scheduled from follow-on schedule check
[2025-07-16T15:25:38.619+0000] {local_task_job_runner.py:222} INFO - ::endgroup::
