[2025-07-16T15:20:30.863+0000] {task_context_logger.py:104} ERROR - Executor reports task instance <TaskInstance: bank_data_pipeline.log_pipeline_failures manual__2025-07-16T15:17:24.318265+00:00 [queued]> finished (failed) although the task says it's queued. (Info: None) Was the task killed externally?
