[2025-07-16T15:22:14.708+0000] {local_task_job_runner.py:120} INFO - ::group::Pre task execution logs
[2025-07-16T15:22:14.758+0000] {taskinstance.py:2076} INFO - Dependencies all met for dep_context=non-requeueable deps ti=<TaskInstance: banking_data_quality_pipeline.generate_banking_data scheduled__2025-07-15T00:00:00+00:00 [queued]>
[2025-07-16T15:22:14.770+0000] {taskinstance.py:2076} INFO - Dependencies all met for dep_context=requeueable deps ti=<TaskInstance: banking_data_quality_pipeline.generate_banking_data scheduled__2025-07-15T00:00:00+00:00 [queued]>
[2025-07-16T15:22:14.770+0000] {taskinstance.py:2306} INFO - Starting attempt 1 of 2
[2025-07-16T15:22:14.784+0000] {taskinstance.py:2330} INFO - Executing <Task(PythonOperator): generate_banking_data> on 2025-07-15 00:00:00+00:00
[2025-07-16T15:22:14.798+0000] {logging_mixin.py:188} WARNING - /home/***/.local/lib/python3.12/site-packages/***/task/task_runner/standard_task_runner.py:61 DeprecationWarning: This process (pid=455) is multi-threaded, use of fork() may lead to deadlocks in the child.
[2025-07-16T15:22:14.800+0000] {standard_task_runner.py:63} INFO - Started process 457 to run task
[2025-07-16T15:22:14.798+0000] {standard_task_runner.py:90} INFO - Running: ['***', 'tasks', 'run', 'banking_data_quality_pipeline', 'generate_banking_data', 'scheduled__2025-07-15T00:00:00+00:00', '--job-id', '5', '--raw', '--subdir', 'DAGS_FOLDER/etl2.py', '--cfg-path', '/tmp/tmps8bw3kk3']
[2025-07-16T15:22:14.801+0000] {standard_task_runner.py:91} INFO - Job 5: Subtask generate_banking_data
[2025-07-16T15:22:14.821+0000] {logging_mixin.py:188} WARNING - /home/***/.local/lib/python3.12/site-packages/***/settings.py:195 DeprecationWarning: The sql_alchemy_conn option in [core] has been moved to the sql_alchemy_conn option in [database] - the old setting has been used, but please update your config.
[2025-07-16T15:22:14.871+0000] {task_command.py:426} INFO - Running <TaskInstance: banking_data_quality_pipeline.generate_banking_data scheduled__2025-07-15T00:00:00+00:00 [running]> on host 4c2c441a4888
[2025-07-16T15:22:14.983+0000] {taskinstance.py:2648} INFO - Exporting env vars: AIRFLOW_CTX_DAG_OWNER='data_team' AIRFLOW_CTX_DAG_ID='banking_data_quality_pipeline' AIRFLOW_CTX_TASK_ID='generate_banking_data' AIRFLOW_CTX_EXECUTION_DATE='2025-07-15T00:00:00+00:00' AIRFLOW_CTX_TRY_NUMBER='1' AIRFLOW_CTX_DAG_RUN_ID='scheduled__2025-07-15T00:00:00+00:00'
[2025-07-16T15:22:14.983+0000] {taskinstance.py:430} INFO - ::endgroup::
[2025-07-16T15:22:15.400+0000] {taskinstance.py:441} INFO - ::group::Post task execution logs
[2025-07-16T15:22:15.400+0000] {taskinstance.py:2905} ERROR - Task failed with exception
Traceback (most recent call last):
  File "/home/airflow/.local/lib/python3.12/site-packages/airflow/models/taskinstance.py", line 465, in _execute_task
    result = _execute_callable(context=context, **execute_callable_kwargs)
             ^^^^^^^^^^^^^^^^^^^^^^^^^^^^^^^^^^^^^^^^^^^^^^^^^^^^^^^^^^^^^
  File "/home/airflow/.local/lib/python3.12/site-packages/airflow/models/taskinstance.py", line 432, in _execute_callable
    return execute_callable(context=context, **execute_callable_kwargs)
           ^^^^^^^^^^^^^^^^^^^^^^^^^^^^^^^^^^^^^^^^^^^^^^^^^^^^^^^^^^^^
  File "/home/airflow/.local/lib/python3.12/site-packages/airflow/models/baseoperator.py", line 400, in wrapper
    return func(self, *args, **kwargs)
           ^^^^^^^^^^^^^^^^^^^^^^^^^^^
  File "/home/airflow/.local/lib/python3.12/site-packages/airflow/operators/python.py", line 235, in execute
    return_value = self.execute_callable()
                   ^^^^^^^^^^^^^^^^^^^^^^^
  File "/home/airflow/.local/lib/python3.12/site-packages/airflow/operators/python.py", line 252, in execute_callable
    return self.python_callable(*self.op_args, **self.op_kwargs)
           ^^^^^^^^^^^^^^^^^^^^^^^^^^^^^^^^^^^^^^^^^^^^^^^^^^^^^
  File "/opt/airflow/dags/etl2.py", line 259, in generate_data_task
    raise Exception(f"Data generation failed: {result.stderr}")
Exception: Data generation failed: Traceback (most recent call last):
  File "/opt/***/src/generate_data.py", line 5, in <module>
    from faker import Faker
ModuleNotFoundError: No module named 'faker'

[2025-07-16T15:22:15.416+0000] {taskinstance.py:1206} INFO - Marking task as UP_FOR_RETRY. dag_id=banking_data_quality_pipeline, task_id=generate_banking_data, run_id=scheduled__2025-07-15T00:00:00+00:00, execution_date=20250715T000000, start_date=20250716T152214, end_date=20250716T152215
[2025-07-16T15:22:15.429+0000] {standard_task_runner.py:110} ERROR - Failed to execute job 5 for task generate_banking_data (Data generation failed: Traceback (most recent call last):
  File "/opt/***/src/generate_data.py", line 5, in <module>
    from faker import Faker
ModuleNotFoundError: No module named 'faker'
; 457)
[2025-07-16T15:22:15.455+0000] {local_task_job_runner.py:240} INFO - Task exited with return code 1
[2025-07-16T15:22:15.501+0000] {taskinstance.py:3498} INFO - 0 downstream tasks scheduled from follow-on schedule check
[2025-07-16T15:22:15.503+0000] {local_task_job_runner.py:222} INFO - ::endgroup::
