[2025-07-16T15:39:38.692+0000] {local_task_job_runner.py:120} INFO - ::group::Pre task execution logs
[2025-07-16T15:39:38.740+0000] {taskinstance.py:2076} INFO - Dependencies all met for dep_context=non-requeueable deps ti=<TaskInstance: bank_data_pipeline.generate_banking_data manual__2025-07-16T15:37:38.606464+00:00 [queued]>
[2025-07-16T15:39:38.751+0000] {taskinstance.py:2076} INFO - Dependencies all met for dep_context=requeueable deps ti=<TaskInstance: bank_data_pipeline.generate_banking_data manual__2025-07-16T15:37:38.606464+00:00 [queued]>
[2025-07-16T15:39:38.751+0000] {taskinstance.py:2306} INFO - Starting attempt 1 of 3
[2025-07-16T15:39:38.767+0000] {taskinstance.py:2330} INFO - Executing <Task(PythonOperator): generate_banking_data> on 2025-07-16 15:37:38.606464+00:00
[2025-07-16T15:39:38.778+0000] {logging_mixin.py:188} WARNING - /home/***/.local/lib/python3.12/site-packages/***/task/task_runner/standard_task_runner.py:61 DeprecationWarning: This process (pid=306) is multi-threaded, use of fork() may lead to deadlocks in the child.
[2025-07-16T15:39:38.779+0000] {standard_task_runner.py:63} INFO - Started process 307 to run task
[2025-07-16T15:39:38.778+0000] {standard_task_runner.py:90} INFO - Running: ['***', 'tasks', 'run', 'bank_data_pipeline', 'generate_banking_data', 'manual__2025-07-16T15:37:38.606464+00:00', '--job-id', '7', '--raw', '--subdir', 'DAGS_FOLDER/bank_data_pipeline.py', '--cfg-path', '/tmp/tmpyrb0ejl4']
[2025-07-16T15:39:38.780+0000] {standard_task_runner.py:91} INFO - Job 7: Subtask generate_banking_data
[2025-07-16T15:39:38.808+0000] {logging_mixin.py:188} WARNING - /home/***/.local/lib/python3.12/site-packages/***/settings.py:195 DeprecationWarning: The sql_alchemy_conn option in [core] has been moved to the sql_alchemy_conn option in [database] - the old setting has been used, but please update your config.
[2025-07-16T15:39:38.866+0000] {task_command.py:426} INFO - Running <TaskInstance: bank_data_pipeline.generate_banking_data manual__2025-07-16T15:37:38.606464+00:00 [running]> on host 0cebe846fd9f
[2025-07-16T15:39:38.989+0000] {taskinstance.py:2648} INFO - Exporting env vars: AIRFLOW_CTX_DAG_OWNER='data_engineering_team' AIRFLOW_CTX_DAG_ID='bank_data_pipeline' AIRFLOW_CTX_TASK_ID='generate_banking_data' AIRFLOW_CTX_EXECUTION_DATE='2025-07-16T15:37:38.606464+00:00' AIRFLOW_CTX_TRY_NUMBER='1' AIRFLOW_CTX_DAG_RUN_ID='manual__2025-07-16T15:37:38.606464+00:00'
[2025-07-16T15:39:38.990+0000] {taskinstance.py:430} INFO - ::endgroup::
[2025-07-16T15:39:39.012+0000] {logging_mixin.py:188} INFO - 2025-07-16 15:39:39,012 - pipeline_logger - INFO - Starting data generation for run manual__2025-07-16T15:37:38.606464+00:00
[2025-07-16T15:39:39.012+0000] {pipeline_logger.py:224} INFO - Starting data generation for run manual__2025-07-16T15:37:38.606464+00:00
[2025-07-16T15:39:39.322+0000] {logging_mixin.py:188} INFO - 2025-07-16 15:39:39,322 - pipeline_logger - ERROR - Pipeline error in generate_banking_data: Data generation failed: Traceback (most recent call last):
  File "/opt/***/src/generate_data_***.py", line 8, in <module>
    from faker import Faker
ModuleNotFoundError: No module named 'faker'
[2025-07-16T15:39:39.322+0000] {pipeline_logger.py:194} ERROR - Pipeline error in generate_banking_data: Data generation failed: Traceback (most recent call last):
  File "/opt/***/src/generate_data_***.py", line 8, in <module>
    from faker import Faker
ModuleNotFoundError: No module named 'faker'

[2025-07-16T15:39:39.336+0000] {logging_mixin.py:188} INFO - 2025-07-16 15:39:39,336 - pipeline_logger - ERROR - Pipeline error in generate_banking_data: Unexpected error in data generation: Data generation failed: Traceback (most recent call last):
  File "/opt/***/src/generate_data_***.py", line 8, in <module>
    from faker import Faker
ModuleNotFoundError: No module named 'faker'
[2025-07-16T15:39:39.336+0000] {pipeline_logger.py:194} ERROR - Pipeline error in generate_banking_data: Unexpected error in data generation: Data generation failed: Traceback (most recent call last):
  File "/opt/***/src/generate_data_***.py", line 8, in <module>
    from faker import Faker
ModuleNotFoundError: No module named 'faker'

[2025-07-16T15:39:39.337+0000] {taskinstance.py:441} INFO - ::group::Post task execution logs
[2025-07-16T15:39:39.361+0000] {taskinstance.py:2905} ERROR - Task failed with exception
Traceback (most recent call last):
  File "/home/airflow/.local/lib/python3.12/site-packages/airflow/models/taskinstance.py", line 465, in _execute_task
    result = _execute_callable(context=context, **execute_callable_kwargs)
             ^^^^^^^^^^^^^^^^^^^^^^^^^^^^^^^^^^^^^^^^^^^^^^^^^^^^^^^^^^^^^
  File "/home/airflow/.local/lib/python3.12/site-packages/airflow/models/taskinstance.py", line 432, in _execute_callable
    return execute_callable(context=context, **execute_callable_kwargs)
           ^^^^^^^^^^^^^^^^^^^^^^^^^^^^^^^^^^^^^^^^^^^^^^^^^^^^^^^^^^^^
  File "/home/airflow/.local/lib/python3.12/site-packages/airflow/models/baseoperator.py", line 400, in wrapper
    return func(self, *args, **kwargs)
           ^^^^^^^^^^^^^^^^^^^^^^^^^^^
  File "/home/airflow/.local/lib/python3.12/site-packages/airflow/operators/python.py", line 235, in execute
    return_value = self.execute_callable()
                   ^^^^^^^^^^^^^^^^^^^^^^^
  File "/home/airflow/.local/lib/python3.12/site-packages/airflow/operators/python.py", line 252, in execute_callable
    return self.python_callable(*self.op_args, **self.op_kwargs)
           ^^^^^^^^^^^^^^^^^^^^^^^^^^^^^^^^^^^^^^^^^^^^^^^^^^^^^
  File "/opt/airflow/dags/bank_data_pipeline.py", line 102, in generate_banking_data
    raise AirflowException(error_msg)
airflow.exceptions.AirflowException: Data generation failed: Traceback (most recent call last):
  File "/opt/***/src/generate_data_***.py", line 8, in <module>
    from faker import Faker
ModuleNotFoundError: No module named 'faker'

[2025-07-16T15:39:39.370+0000] {taskinstance.py:1206} INFO - Marking task as UP_FOR_RETRY. dag_id=bank_data_pipeline, task_id=generate_banking_data, run_id=manual__2025-07-16T15:37:38.606464+00:00, execution_date=20250716T153738, start_date=20250716T153938, end_date=20250716T153939
[2025-07-16T15:39:39.391+0000] {standard_task_runner.py:110} ERROR - Failed to execute job 7 for task generate_banking_data (Data generation failed: Traceback (most recent call last):
  File "/opt/***/src/generate_data_***.py", line 8, in <module>
    from faker import Faker
ModuleNotFoundError: No module named 'faker'
; 307)
[2025-07-16T15:39:39.435+0000] {local_task_job_runner.py:240} INFO - Task exited with return code 1
[2025-07-16T15:39:39.490+0000] {taskinstance.py:3498} INFO - 0 downstream tasks scheduled from follow-on schedule check
[2025-07-16T15:39:39.492+0000] {local_task_job_runner.py:222} INFO - ::endgroup::
